Workbook

Sheet SL
A1: 产品 | C1: 销售情况$ | W1: 广告$ | AG1: 销售成本$ | AP1: 退款成本$ 退款部分的销售金额=系统退款金额/(1-0.15+0.2*0.15) | BA1: 汇总$
C2: 输入 | M2: 公式输出 | W2: 输入 | AC2: 公式输出 | AG2: 输入 | AJ2: 公式输出 | AP2: 输入 | AS2: 公式输出
A3: 日期 | B3: 周数 | C3: 销量 | D3: 订单量 | E3: 销售额 | F3: 促销销量 | G3: 促销订单量 | H3: 促销销售额 | I3: 促销折扣 | J3: 退款量 | K3: 退款率 | L3: 退款金额 | M3: 销量环比 | N3: 订单环比 | O3: 销售额环比 | P3: 客单 销量 | Q3: 客单 价格($) | R3: 销售 均价($) | S3: 日均 销量 | T3: 自然 订单 | U3: 自然单 占比(%) | V3: TAcos (%) | W3: 展示 | X3: 点击 | Y3: 广告订单量 | Z3: 广告花费 | AA3: 广告销售额 | AB3: CPC | AC3: Acos(%) | AD3: CTR(%) | AE3: CVR(%) | AF3: CPS(%) | AG3: 3.6FT | AH3: 5.0FT | AI3: 5.5FT | AJ3: 产品成本 | AK3: 头程 | AL3: 入仓费 | AM3: FBA物流 | AN3: 佣金 | AO3: 成本小结 | AP3: 退款3.6FT | AQ3: 退款5.0FT | AR3: 退款5.5FT | AS3: 退款 销售金额 | AT3: 退款 产品成本 | AU3: 退款头程 | AV3: 退款 入仓费 | AW3: 退款 FBA物流 | AX3: 退款佣金 | AY3: 退款 管理费用 佣金的20% | AZ3: 退款 成本小结 | BA3: 净成本 | BB3: 净销售额 | BC3: 净销售额 (-退款金额) | BD3: 毛利 | BE3: 毛利率 | BF3: BSR | BG3: 备注 | BH3: 促销 | BI3: 备用
A4: 1104~1110 | B4: 2024W45 | C4: 276 | D4: 264 | E4: 6073.25 | J4: 12 | K4: =J4/C4 -> 0.043478261 | L4: 243.5 | M4: =(C4-C3)/C3 -> #VALUE! | N4: =(D4-D3)/D3 -> #VALUE! | O4: =(E4-E3)/E3 -> #VALUE! | P4: =C4/D4 -> 1.0454545 | Q4: =E4/D4 -> 23.004735 | R4: =E4/C4 -> 22.004529 | S4: =C4/7 -> 39.428571 | T4: =D4-Y4 -> 111 | U4: =T4/D4 -> 0.42045455 | V4: =Z4/(E4-I4) -> 0.28145062 | W4: 136418 | X4: 1723 | Y4: 153 | Z4: 1709.32 | AA4: 3516.2 | AB4: 0.99 | AC4: =Z4/AA4 -> 0.48612707 | AD4: =X4/W4 -> 0.012630298 | AE4: =Y4/X4 -> 0.088798607 | AF4: =Z4/Y4 -> 11.172026 | AG4: 68 | AH4: 203 | AI4: 5 | AJ4: =AG4*产品成本!$D$2+AH4*产品成本!$D$3+AI4*产品成本!$D$4 -> 589.08451 | AK4: =AG4*产品成本!$E$2+AH4*产品成本!$E$3+AI4*产品成本!$E$4 -> 51.991677 | AL4: =AG4*产品成本!$F$2+AH4*产品成本!$F$3+AI4*产品成本!$F$4 -> 93.84 | AM4: =AG4*产品成本!$G$2+AH4*产品成本!$G$3+AI4*产品成本!$G$4 -> 1062.12 | AN4: =(E4-I4)*0.15 -> 910.9875 | AO4: =SUM(AJ4:AN4) -> 2708.0237 | AP4: 3 | AQ4: 9 | AR4: 0 | AS4: =L4/(1-0.15+0.15*0.2) -> 276.70455 | AT4: =AP4*产品成本!$D$2+AQ4*产品成本!$D$3+AR4*产品成本!$D$4 -> 25.352113 | AU4: =AP4*产品成本!$E$2+AQ4*产品成本!$E$3+AR4*产品成本!$E$4 -> 2.2559324 | AV4: =AP4*产品成本!$F$2+AQ4*产品成本!$F$3+AR4*产品成本!$F$4 -> 4.08 | AW4: 0 | AX4: =AS4*0.15 -> 41.505682 | AY4: =-AX4*0.2 -> -8.3011364 | AZ4: =SUM(AT4:AY4) -> 64.892591 | BA4: =AO4-AZ4 -> 2643.1311 | BB4: =E4-I4 -> 6073.25 | BC4: =E4-AS4-I4 -> 5796.5455 | BD4: =BC4-BA4-Z4 -> 1444.0944 | BE4: =BD4/BC4 -> 0.24913017
A5: 1111~1117 | B5: 2024W46 | C5: 296 | D5: 285 | E5: 6535.75 | J5: 12 | K5: =J5/C5 -> 0.040540541 | L5: 240.45 | M5: =(C5-C4)/C4 -> 0.072463768 | N5: =(D5-D4)/D4 -> 0.079545455 | O5: =(E5-E4)/E4 -> 0.076153625 | P5: =C5/D5 -> 1.0385965 | Q5: =E5/D5 -> 22.932456 | R5: =E5/C5 -> 22.080236 | S5: =C5/7 -> 42.285714 | T5: =D5-Y5 -> 94 | U5: =T5/D5 -> 0.32982456 | V5: =Z5/(E5-I5) -> 0.28953525 | W5: 184745 | X5: 1929 | Y5: 191 | Z5: 1892.33 | AA5: 4333.92 | AB5: 0.98 | AC5: =Z5/AA5 -> 0.43663243 | AD5: =X5/W5 -> 0.010441419 | AE5: =Y5/X5 -> 0.099015034 | AF5: =Z5/Y5 -> 9.9074869 | AG5: 68 | AH5: 216 | AI5: 12 | AJ5: =AG5*产品成本!$D$2+AH5*产品成本!$D$3+AI5*产品成本!$D$4 -> 639.71831 | AK5: =AG5*产品成本!$E$2+AH5*产品成本!$E$3+AI5*产品成本!$E$4 -> 55.967949 | AL5: =AG5*产品成本!$F$2+AH5*产品成本!$F$3+AI5*产品成本!$F$4 -> 100.64 | AM5: =AG5*产品成本!$G$2+AH5*产品成本!$G$3+AI5*产品成本!$G$4 -> 1140.12 | AN5: =(E5-I5)*0.15 -> 980.3625 | AO5: =SUM(AJ5:AN5) -> 2916.8088 | AP5: 3 | AQ5: 9 | AR5: 0 | AS5: =L5/(1-0.15+0.15*0.2) -> 273.23864 | AT5: =AP5*产品成本!$D$2+AQ5*产品成本!$D$3+AR5*产品成本!$D$4 -> 25.352113 | AU5: =AP5*产品成本!$E$2+AQ5*产品成本!$E$3+AR5*产品成本!$E$4 -> 2.2559324 | AV5: =AP5*产品成本!$F$2+AQ5*产品成本!$F$3+AR5*产品成本!$F$4 -> 4.08 | AW5: 0 | AX5: =AS5*0.15 -> 40.985795 | AY5: =-AX5*0.2 -> -8.1971591 | AZ5: =SUM(AT5:AY5) -> 64.476681 | BA5: =AO5-AZ5 -> 2852.3321 | BB5: =E5-I5 -> 6535.75 | BC5: =E5-AS5-I5 -> 6262.5114 | BD5: =BC5-BA5-Z5 -> 1517.8493 | BE5: =BD5/BC5 -> 0.2423707
A6: 1118~1124 | B6: 2024W47 | C6: 401 | D6: 366 | E6: 7627.49 | J6: 16 | K6: =J6/C6 -> 0.039900249 | L6: 329.15 | M6: =(C6-C5)/C5 -> 0.35472973 | N6: =(D6-D5)/D5 -> 0.28421053 | O6: =(E6-E5)/E5 -> 0.16704127 | P6: =C6/D6 -> 1.0956284 | Q6: =E6/D6 -> 20.840137 | R6: =E6/C6 -> 19.021172 | S6: =C6/7 -> 57.285714 | T6: =D6-Y6 -> 126 | U6: =T6/D6 -> 0.3442623 | V6: =Z6/(E6-I6) -> 0.28473194 | W6: 195302 | X6: 2172 | Y6: 240 | Z6: 2171.79 | AA6: 4918.97 | AB6: ‎1.00 | AC6: =Z6/AA6 -> 0.44151316 | AD6: =X6/W6 -> 0.011121238 | AE6: =Y6/X6 -> 0.11049724 | AF6: =Z6/Y6 -> 9.049125 | AG6: 119 | AH6: 271 | AI6: 11 | AJ6: =AG6*产品成本!$D$2+AH6*产品成本!$D$3+AI6*产品成本!$D$4 -> 860.35211 | AK6: =AG6*产品成本!$E$2+AH6*产品成本!$E$3+AI6*产品成本!$E$4 -> 75.215366 | AL6: =AG6*产品成本!$F$2+AH6*产品成本!$F$3+AI6*产品成本!$F$4 -> 136.34 | AM6: =AG6*产品成本!$G$2+AH6*产品成本!$G$3+AI6*产品成本!$G$4 -> 1538.91 | AN6: =(E6-I6)*0.15 -> 1144.1235 | AO6: =SUM(AJ6:AN6) -> 3754.941 | AP6: 2 | AQ6: 14 | AR6: 1 | AS6: =L6/(1-0.15+0.15*0.2) -> 374.03409 | AT6: =AP6*产品成本!$D$2+AQ6*产品成本!$D$3+AR6*产品成本!$D$4 -> 37.112676 | AU6: =AP6*产品成本!$E$2+AQ6*产品成本!$E$3+AR6*产品成本!$E$4 -> 3.2562761 | AV6: =AP6*产品成本!$F$2+AQ6*产品成本!$F$3+AR6*产品成本!$F$4 -> 5.78 | AW6: 0 | AX6: =AS6*0.15 -> 56.105114 | AY6: =-AX6*0.2 -> -11.221023 | AZ6: =SUM(AT6:AY6) -> 91.033043 | BA6: =AO6-AZ6 -> 3663.9079 | BB6: =E6-I6 -> 7627.49 | BC6: =E6-AS6-I6 -> 7253.4559 | BD6: =BC6-BA6-Z6 -> 1417.758 | BE6: =BD6/BC6 -> 0.19545965
A7: 1125~1201 | B7: 2024W48 | C7: 349 | D7: 339 | E7: 6352.41 | J7: 22 | K7: =J7/C7 -> 0.063037249 | L7: 390.12 | M7: =(C7-C6)/C6 -> -0.12967581 | N7: =(D7-D6)/D6 -> -0.073770492 | O7: =(E7-E6)/E6 -> -0.16716902 | P7: =C7/D7 -> 1.0294985 | Q7: =E7/D7 -> 18.738673 | R7: =E7/C7 -> 18.201748 | S7: =C7/7 -> 49.857143 | T7: =D7-Y7 -> 118 | U7: =T7/D7 -> 0.3480826 | V7: =Z7/(E7-I7) -> 0.35467799 | W7: 204302 | X7: 2295 | Y7: 221 | Z7: 2253.06 | AA7: 4084.24 | AB7: ‎0.98 | AC7: =Z7/AA7 -> 0.55164731 | AD7: =X7/W7 -> 0.01123337 | AE7: =Y7/X7 -> 0.096296296 | AF7: =Z7/Y7 -> 10.194842 | AG7: 129 | AH7: 196 | AI7: 24 | AJ7: =AG7*产品成本!$D$2+AH7*产品成本!$D$3+AI7*产品成本!$D$4 -> 766.05634 | AK7: =AG7*产品成本!$E$2+AH7*产品成本!$E$3+AI7*产品成本!$E$4 -> 65.222176 | AL7: =AG7*产品成本!$F$2+AH7*产品成本!$F$3+AI7*产品成本!$F$4 -> 118.66 | AM7: =AG7*产品成本!$G$2+AH7*产品成本!$G$3+AI7*产品成本!$G$4 -> 1334.01 | AN7: =(E7-I7)*0.15 -> 952.8615 | AO7: =SUM(AJ7:AN7) -> 3236.81 | AP7: 6 | AQ7: 16 | AR7: 0 | AS7: =L7/(1-0.15+0.15*0.2) -> 443.31818 | AT7: =AP7*产品成本!$D$2+AQ7*产品成本!$D$3+AR7*产品成本!$D$4 -> 46.478873 | AU7: =AP7*产品成本!$E$2+AQ7*产品成本!$E$3+AR7*产品成本!$E$4 -> 4.1262845 | AV7: =AP7*产品成本!$F$2+AQ7*产品成本!$F$3+AR7*产品成本!$F$4 -> 7.48 | AW7: 0 | AX7: =AS7*0.15 -> 66.497727 | AY7: =-AX7*0.2 -> -13.299545 | AZ7: =SUM(AT7:AY7) -> 111.28334 | BA7: =AO7-AZ7 -> 3125.5267 | BB7: =E7-I7 -> 6352.41 | BC7: =E7-AS7-I7 -> 5909.0918 | BD7: =BC7-BA7-Z7 -> 530.50514 | BE7: =BD7/BC7 -> 0.08977778
A8: 1202~1208 | B8: 2024W49 | C8: 319 | D8: 300 | E8: 6697.47 | J8: 23 | K8: =J8/C8 -> 0.072100313 | L8: 402.29 | M8: =(C8-C7)/C7 -> -0.085959885 | N8: =(D8-D7)/D7 -> -0.11504425 | O8: =(E8-E7)/E7 -> 0.054319542 | P8: =C8/D8 -> 1.0633333 | Q8: =E8/D8 -> 22.3249 | R8: =E8/C8 -> 20.995204 | S8: =C8/7 -> 45.571429 | T8: =D8-Y8 -> 122 | U8: =T8/D8 -> 0.40666667 | V8: =Z8/(E8-I8) -> 0.32161846 | W8: 215967 | X8: 2203 | Y8: 178 | Z8: 2154.03 | AA8: 4084.54 | AB8: ‎0.98 | AC8: =Z8/AA8 -> 0.52736171 | AD8: =X8/W8 -> 0.010200633 | AE8: =Y8/X8 -> 0.080798911 | AF8: =Z8/Y8 -> 12.101292 | AG8: 106 | AH8: 197 | AI8: 16 | AJ8: =AG8*产品成本!$D$2+AH8*产品成本!$D$3+AI8*产品成本!$D$4 -> 693.09859 | AK8: =AG8*产品成本!$E$2+AH8*产品成本!$E$3+AI8*产品成本!$E$4 -> 59.742004 | AL8: =AG8*产品成本!$F$2+AH8*产品成本!$F$3+AI8*产品成本!$F$4 -> 108.46 | AM8: =AG8*产品成本!$G$2+AH8*产品成本!$G$3+AI8*产品成本!$G$4 -> 1221.84 | AN8: =(E8-I8)*0.15 -> 1004.6205 | AO8: =SUM(AJ8:AN8) -> 3087.7611 | AP8: 10 | AQ8: 13 | AR8: 2 | AS8: =L8/(1-0.15+0.15*0.2) -> 457.14773 | AT8: =AP8*产品成本!$D$2+AQ8*产品成本!$D$3+AR8*产品成本!$D$4 -> 55.211268 | AU8: =AP8*产品成本!$E$2+AQ8*产品成本!$E$3+AR8*产品成本!$E$4 -> 4.6623423 | AV8: =AP8*产品成本!$F$2+AQ8*产品成本!$F$3+AR8*产品成本!$F$4 -> 8.5 | AW8: 0 | AX8: =AS8*0.15 -> 68.572159 | AY8: =-AX8*0.2 -> -13.714432 | AZ8: =SUM(AT8:AY8) -> 123.23134 | BA8: =AO8-AZ8 -> 2964.5298 | BB8: =E8-I8 -> 6697.47 | BC8: =E8-AS8-I8 -> 6240.3223 | BD8: =BC8-BA8-Z8 -> 1121.7625 | BE8: =BD8/BC8 -> 0.17976035
A9: 1209~1215 | B9: 2024W50 | C9: 299 | D9: 285 | E9: 7065.55 | J9: 21 | K9: =J9/C9 -> 0.070234114 | L9: 418.94 | M9: =(C9-C8)/C8 -> -0.062695925 | N9: =(D9-D8)/D8 -> -0.05 | O9: =(E9-E8)/E8 -> 0.054958066 | P9: =C9/D9 -> 1.0491228 | Q9: =E9/D9 -> 24.791404 | R9: =E9/C9 -> 23.630602 | S9: =C9/7 -> 42.714286 | T9: =D9-Y9 -> 93 | U9: =T9/D9 -> 0.32631579 | V9: =Z9/(E9-I9) -> 0.24653849 | W9: 158506 | X9: 1791 | Y9: 192 | Z9: 1741.93 | AA9: 4780.29 | AB9: ‎0.97 | AC9: =Z9/AA9 -> 0.36439839 | AD9: =X9/W9 -> 0.011299257 | AE9: =Y9/X9 -> 0.10720268 | AF9: =Z9/Y9 -> 9.0725521 | AG9: 98 | AH9: 187 | AI9: 14 | AJ9: =AG9*产品成本!$D$2+AH9*产品成本!$D$3+AI9*产品成本!$D$4 -> 648.4507 | AK9: =AG9*产品成本!$E$2+AH9*产品成本!$E$3+AI9*产品成本!$E$4 -> 56.005246 | AL9: =AG9*产品成本!$F$2+AH9*产品成本!$F$3+AI9*产品成本!$F$4 -> 101.66 | AM9: =AG9*产品成本!$G$2+AH9*产品成本!$G$3+AI9*产品成本!$G$4 -> 1145.52 | AN9: =(E9-I9)*0.15 -> 1059.8325 | AO9: =SUM(AJ9:AN9) -> 3011.4685 | AP9: 6 | AQ9: 15 | AR9: 2 | AS9: =L9/(1-0.15+0.15*0.2) -> 476.06818 | AT9: =AP9*产品成本!$D$2+AQ9*产品成本!$D$3+AR9*产品成本!$D$4 -> 50.985915 | AU9: =AP9*产品成本!$E$2+AQ9*产品成本!$E$3+AR9*产品成本!$E$4 -> 4.3534944 | AV9: =AP9*产品成本!$F$2+AQ9*产品成本!$F$3+AR9*产品成本!$F$4 -> 7.82 | AW9: 0 | AX9: =AS9*0.15 -> 71.410227 | AY9: =-AX9*0.2 -> -14.282045 | AZ9: =SUM(AT9:AY9) -> 120.28759 | BA9: =AO9-AZ9 -> 2891.1809 | BB9: =E9-I9 -> 7065.55 | BC9: =E9-AS9-I9 -> 6589.4818 | BD9: =BC9-BA9-Z9 -> 1956.371 | BE9: =BD9/BC9 -> 0.29689299
A10: 1216~1222 | B10: 2024W51 | C10: 261 | D10: 250 | E10: 6230.89 | J10: 29 | K10: =J10/C10 -> 0.11111111 | L10: 586.11 | M10: =(C10-C9)/C9 -> -0.1270903 | N10: =(D10-D9)/D9 -> -0.12280702 | O10: =(E10-E9)/E9 -> -0.11813093 | P10: =C10/D10 -> 1.044 | Q10: =E10/D10 -> 24.92356 | R10: =E10/C10 -> 23.873142 | S10: =C10/7 -> 37.285714 | T10: =D10-Y10 -> 110 | U10: =T10/D10 -> 0.44 | V10: =Z10/(E10-I10) -> 0.27256941 | W10: 166059 | X10: 1726 | Y10: 140 | Z10: 1698.35 | AA10: 3468.95 | AB10: ‎0.98 | AC10: =Z10/AA10 -> 0.48958619 | AD10: =X10/W10 -> 0.010393896 | AE10: =Y10/X10 -> 0.081112399 | AF10: =Z10/Y10 -> 12.131071 | AG10: 76 | AH10: 160 | AI10: 26 | AJ10: =AG10*产品成本!$D$2+AH10*产品成本!$D$3+AI10*产品成本!$D$4 -> 584.64789 | AK10: =AG10*产品成本!$E$2+AH10*产品成本!$E$3+AI10*产品成本!$E$4 -> 49.500558 | AL10: =AG10*产品成本!$F$2+AH10*产品成本!$F$3+AI10*产品成本!$F$4 -> 89.08 | AM10: =AG10*产品成本!$G$2+AH10*产品成本!$G$3+AI10*产品成本!$G$4 -> 1005.84 | AN10: =(E10-I10)*0.15 -> 934.6335 | AO10: =SUM(AJ10:AN10) -> 2663.7019 | AP10: 12 | AQ10: 14 | AR10: 3 | AS10: =L10/(1-0.15+0.15*0.2) -> 666.03409 | AT10: =AP10*产品成本!$D$2+AQ10*产品成本!$D$3+AR10*产品成本!$D$4 -> 64.859155 | AU10: =AP10*产品成本!$E$2+AQ10*产品成本!$E$3+AR10*产品成本!$E$4 -> 5.4123465 | AV10: =AP10*产品成本!$F$2+AQ10*产品成本!$F$3+AR10*产品成本!$F$4 -> 9.86 | AW10: 0 | AX10: =AS10*0.15 -> 99.905114 | AY10: =-AX10*0.2 -> -19.981023 | AZ10: =SUM(AT10:AY10) -> 160.05559 | BA10: =AO10-AZ10 -> 2503.6464 | BB10: =E10-I10 -> 6230.89 | BC10: =E10-AS10-I10 -> 5564.8559 | BD10: =BC10-BA10-Z10 -> 1362.8596 | BE10: =BD10/BC10 -> 0.24490473
A11: 1223~1229 | B11: 2024W52 | C11: 305 | D11: 290 | E11: 6636.34 | J11: 18 | K11: =J11/C11 -> 0.059016393 | L11: 268.6 | M11: =(C11-C10)/C10 -> 0.16858238 | N11: =(D11-D10)/D10 -> 0.16 | O11: =(E11-E10)/E10 -> 0.065070961 | P11: =C11/D11 -> 1.0517241 | Q11: =E11/D11 -> 22.883931 | R11: =E11/C11 -> 21.758492 | S11: =C11/7 -> 43.571429 | T11: =D11-Y11 -> 95 | U11: =T11/D11 -> 0.32758621 | V11: =Z11/(E11-I11) -> 0.3061115 | W11: 175575 | X11: 1917 | Y11: 195 | Z11: 2031.46 | AA11: 4467.78 | AB11: ‎1.06 | AC11: =Z11/AA11 -> 0.45469114 | AD11: =X11/W11 -> 0.010918411 | AE11: =Y11/X11 -> 0.10172144 | AF11: =Z11/Y11 -> 10.417744 | AG11: 97 | AH11: 170 | AI11: 38 | AJ11: =AG11*产品成本!$D$2+AH11*产品成本!$D$3+AI11*产品成本!$D$4 -> 689.85915 | AK11: =AG11*产品成本!$E$2+AH11*产品成本!$E$3+AI11*产品成本!$E$4 -> 57.594207 | AL11: =AG11*产品成本!$F$2+AH11*产品成本!$F$3+AI11*产品成本!$F$4 -> 103.7 | AM11: =AG11*产品成本!$G$2+AH11*产品成本!$G$3+AI11*产品成本!$G$4 -> 1169.13 | AN11: =(E11-I11)*0.15 -> 995.451 | AO11: =SUM(AJ11:AN11) -> 3015.7344 | AP11: 7 | AQ11: 11 | AR11: 0 | AS11: =L11/(1-0.15+0.15*0.2) -> 305.22727 | AT11: =AP11*产品成本!$D$2+AQ11*产品成本!$D$3+AR11*产品成本!$D$4 -> 38.028169 | AU11: =AP11*产品成本!$E$2+AQ11*产品成本!$E$3+AR11*产品成本!$E$4 -> 3.3359408 | AV11: =AP11*产品成本!$F$2+AQ11*产品成本!$F$3+AR11*产品成本!$F$4 -> 6.12 | AW11: 0 | AX11: =AS11*0.15 -> 45.784091 | AY11: =-AX11*0.2 -> -9.1568182 | AZ11: =SUM(AT11:AY11) -> 84.111383 | BA11: =AO11-AZ11 -> 2931.623 | BB11: =E11-I11 -> 6636.34 | BC11: =E11-AS11-I11 -> 6331.1127 | BD11: =BC11-BA11-Z11 -> 1368.0297 | BE11: =BD11/BC11 -> 0.21608046
A12: 1230~0105 | B12: 2025W01 | C12: 351 | D12: 331 | E12: 7526.09 | J12: 21 | K12: =J12/C12 -> 0.05982906 | L12: 410.76 | M12: =(C12-C11)/C11 -> 0.15081967 | N12: =(D12-D11)/D11 -> 0.14137931 | O12: =(E12-E11)/E11 -> 0.1340724 | P12: =C12/D12 -> 1.060423 | Q12: =E12/D12 -> 22.737432 | R12: =E12/C12 -> 21.441852 | S12: =C12/7 -> 50.142857 | T12: =D12-Y12 -> 139 | U12: =T12/D12 -> 0.41993958 | V12: =Z12/(E12-I12) -> 0.26822693 | W12: 197397 | X12: 2078 | Y12: 192 | Z12: 2018.7 | AA12: 4366.84 | AB12: ‎0.97 | AC12: =Z12/AA12 -> 0.46227936 | AD12: =X12/W12 -> 0.010527009 | AE12: =Y12/X12 -> 0.092396535 | AF12: =Z12/Y12 -> 10.514062 | AG12: 112 | AH12: 212 | AI12: 27 | AJ12: =AG12*产品成本!$D$2+AH12*产品成本!$D$3+AI12*产品成本!$D$4 -> 773.87324 | AK12: =AG12*产品成本!$E$2+AH12*产品成本!$E$3+AI12*产品成本!$E$4 -> 65.985499 | AL12: =AG12*产品成本!$F$2+AH12*产品成本!$F$3+AI12*产品成本!$F$4 -> 119.34 | AM12: =AG12*产品成本!$G$2+AH12*产品成本!$G$3+AI12*产品成本!$G$4 -> 1345.38 | AN12: =(E12-I12)*0.15 -> 1128.9135 | AO12: =SUM(AJ12:AN12) -> 3433.4922 | AP12: 5 | AQ12: 14 | AR12: 2 | AS12: =L12/(1-0.15+0.15*0.2) -> 466.77273 | AT12: =AP12*产品成本!$D$2+AQ12*产品成本!$D$3+AR12*产品成本!$D$4 -> 46.760563 | AU12: =AP12*产品成本!$E$2+AQ12*产品成本!$E$3+AR12*产品成本!$E$4 -> 3.9870972 | AV12: =AP12*产品成本!$F$2+AQ12*产品成本!$F$3+AR12*产品成本!$F$4 -> 7.14 | AW12: 0 | AX12: =AS12*0.15 -> 70.015909 | AY12: =-AX12*0.2 -> -14.003182 | AZ12: =SUM(AT12:AY12) -> 113.90039 | BA12: =AO12-AZ12 -> 3319.5919 | BB12: =E12-I12 -> 7526.09 | BC12: =E12-AS12-I12 -> 7059.3173 | BD12: =BC12-BA12-Z12 -> 1721.0254 | BE12: =BD12/BC12 -> 0.24379488 | BG12: 九折
A13: 0106~0112 | B13: 2025W02 | C13: 290 | D13: 271 | E13: 6846.76 | J13: 25 | K13: =J13/C13 -> 0.086206897 | L13: 471.02 | M13: =(C13-C12)/C12 -> -0.17378917 | N13: =(D13-D12)/D12 -> -0.18126888 | O13: =(E13-E12)/E12 -> -0.090263337 | P13: =C13/D13 -> 1.0701107 | Q13: =E13/D13 -> 25.264797 | R13: =E13/C13 -> 23.609517 | S13: =C13/7 -> 41.428571 | T13: =D13-Y13 -> 104 | U13: =T13/D13 -> 0.38376384 | V13: =Z13/(E13-I13) -> 0.2637262 | W13: 175351 | X13: 1841 | Y13: 167 | Z13: 1805.67 | AA13: 4166.77 | AB13: ‎0.98 | AC13: =Z13/AA13 -> 0.43335005 | AD13: =X13/W13 -> 0.010498942 | AE13: =Y13/X13 -> 0.09071157 | AF13: =Z13/Y13 -> 10.812395 | AG13: 81 | AH13: 199 | AI13: 10 | AJ13: =AG13*产品成本!$D$2+AH13*产品成本!$D$3+AI13*产品成本!$D$4 -> 624.64789 | AK13: =AG13*产品成本!$E$2+AH13*产品成本!$E$3+AI13*产品成本!$E$4 -> 54.527408 | AL13: =AG13*产品成本!$F$2+AH13*产品成本!$F$3+AI13*产品成本!$F$4 -> 98.6 | AM13: =AG13*产品成本!$G$2+AH13*产品成本!$G$3+AI13*产品成本!$G$4 -> 1113.99 | AN13: =(E13-I13)*0.15 -> 1027.014 | AO13: =SUM(AJ13:AN13) -> 2918.7793 | AP13: 7 | AQ13: 15 | AR13: 3 | AS13: =L13/(1-0.15+0.15*0.2) -> 535.25 | AT13: =AP13*产品成本!$D$2+AQ13*产品成本!$D$3+AR13*产品成本!$D$4 -> 56.408451 | AU13: =AP13*产品成本!$E$2+AQ13*产品成本!$E$3+AR13*产品成本!$E$4 -> 4.7371014 | AV13: =AP13*产品成本!$F$2+AQ13*产品成本!$F$3+AR13*产品成本!$F$4 -> 8.5 | AW13: 0 | AX13: =AS13*0.15 -> 80.2875 | AY13: =-AX13*0.2 -> -16.0575 | AZ13: =SUM(AT13:AY13) -> 133.87555 | BA13: =AO13-AZ13 -> 2784.9037 | BB13: =E13-I13 -> 6846.76 | BC13: =E13-AS13-I13 -> 6311.51 | BD13: =BC13-BA13-Z13 -> 1720.9363 | BE13: =BD13/BC13 -> 0.27266633 | BG13: 原价
A14: 0113~0119 | B14: 2025W03 | C14: 315 | D14: 298 | E14: 7220.89 | J14: 26 | K14: =J14/C14 -> 0.082539683 | L14: 508.77 | M14: =(C14-C13)/C13 -> 0.086206897 | N14: =(D14-D13)/D13 -> 0.099630996 | O14: =(E14-E13)/E13 -> 0.054643364 | P14: =C14/D14 -> 1.057047 | Q14: =E14/D14 -> 24.231174 | R14: =E14/C14 -> 22.92346 | S14: =C14/7 -> 45 | T14: =D14-Y14 -> 105 | U14: =T14/D14 -> 0.35234899 | V14: =Z14/(E14-I14) -> 0.28568362 | W14: 192908 | X14: 2120 | Y14: 193 | Z14: 2062.89 | AA14: 4629.61 | AB14: ‎0.97 | AC14: =Z14/AA14 -> 0.44558613 | AD14: =X14/W14 -> 0.010989695 | AE14: =Y14/X14 -> 0.091037736 | AF14: =Z14/Y14 -> 10.688549 | AG14: 80 | AH14: 212 | AI14: 23 | AJ14: =AG14*产品成本!$D$2+AH14*产品成本!$D$3+AI14*产品成本!$D$4 -> 693.02817 | AK14: =AG14*产品成本!$E$2+AH14*产品成本!$E$3+AI14*产品成本!$E$4 -> 59.590073 | AL14: =AG14*产品成本!$F$2+AH14*产品成本!$F$3+AI14*产品成本!$F$4 -> 107.1 | AM14: =AG14*产品成本!$G$2+AH14*产品成本!$G$3+AI14*产品成本!$G$4 -> 1211.7 | AN14: =(E14-I14)*0.15 -> 1083.1335 | AO14: =SUM(AJ14:AN14) -> 3154.5517 | AP14: 8 | AQ14: 16 | AR14: 2 | AS14: =L14/(1-0.15+0.15*0.2) -> 578.14773 | AT14: =AP14*产品成本!$D$2+AQ14*产品成本!$D$3+AR14*产品成本!$D$4 -> 57.323944 | AU14: =AP14*产品成本!$E$2+AQ14*产品成本!$E$3+AR14*产品成本!$E$4 -> 4.8934986 | AV14: =AP14*产品成本!$F$2+AQ14*产品成本!$F$3+AR14*产品成本!$F$4 -> 8.84 | AW14: 0 | AX14: =AS14*0.15 -> 86.722159 | AY14: =-AX14*0.2 -> -17.344432 | AZ14: =SUM(AT14:AY14) -> 140.43517 | BA14: =AO14-AZ14 -> 3014.1166 | BB14: =E14-I14 -> 7220.89 | BC14: =E14-AS14-I14 -> 6642.7423 | BD14: =BC14-BA14-Z14 -> 1565.7357 | BE14: =BD14/BC14 -> 0.23570622 | BG14: 平日原价, 周末九折 平日销量一般，周末拉升
A15: 0120~0126 | B15: 2025W04 | C15: 278 | D15: 269 | E15: 6436.56 | J15: 23 | K15: =J15/C15 -> 0.082733813 | L15: 471.54 | M15: =(C15-C14)/C14 -> -0.11746032 | N15: =(D15-D14)/D14 -> -0.097315436 | O15: =(E15-E14)/E14 -> -0.10861957 | P15: =C15/D15 -> 1.0334572 | Q15: =E15/D15 -> 23.927732 | R15: =E15/C15 -> 23.153094 | S15: =C15/7 -> 39.714286 | T15: =D15-Y15 -> 100 | U15: =T15/D15 -> 0.37174721 | V15: =Z15/(E15-I15) -> 0.27666486 | W15: 167353 | X15: 1833 | Y15: 169 | Z15: 1780.77 | AA15: 4021.03 | AB15: ‎0.97 | AC15: =Z15/AA15 -> 0.44286414 | AD15: =X15/W15 -> 0.010952896 | AE15: =Y15/X15 -> 0.092198582 | AF15: =Z15/Y15 -> 10.537101 | AG15: 49 | AH15: 177 | AI15: 52 | AJ15: =AG15*产品成本!$D$2+AH15*产品成本!$D$3+AI15*产品成本!$D$4 -> 649.57746 | AK15: =AG15*产品成本!$E$2+AH15*产品成本!$E$3+AI15*产品成本!$E$4 -> 53.5506 | AL15: =AG15*产品成本!$F$2+AH15*产品成本!$F$3+AI15*产品成本!$F$4 -> 94.52 | AM15: =AG15*产品成本!$G$2+AH15*产品成本!$G$3+AI15*产品成本!$G$4 -> 1073.91 | AN15: =(E15-I15)*0.15 -> 965.484 | AO15: =SUM(AJ15:AN15) -> 2837.0421 | AP15: 10 | AQ15: 13 | AR15: 1 | AS15: =L15/(1-0.15+0.15*0.2) -> 535.84091 | AT15: =AP15*产品成本!$D$2+AQ15*产品成本!$D$3+AR15*产品成本!$D$4 -> 51.901408 | AU15: =AP15*产品成本!$E$2+AQ15*产品成本!$E$3+AR15*产品成本!$E$4 -> 4.4523423 | AV15: =AP15*产品成本!$F$2+AQ15*产品成本!$F$3+AR15*产品成本!$F$4 -> 8.16 | AW15: 0 | AX15: =AS15*0.15 -> 80.376136 | AY15: =-AX15*0.2 -> -16.075227 | AZ15: =SUM(AT15:AY15) -> 128.81466 | BA15: =AO15-AZ15 -> 2708.2274 | BB15: =E15-I15 -> 6436.56 | BC15: =E15-AS15-I15 -> 5900.7191 | BD15: =BC15-BA15-Z15 -> 1411.7217 | BE15: =BD15/BC15 -> 0.2392457 | BG15: 新P陆续到货，老P毛利环比减少$631.19
A16: 0127~0202 | B16: 2025W05 | C16: 344 | D16: 324 | E16: 7634.97 | J16: 30 | K16: =J16/C16 -> 0.087209302 | L16: 583.82 | M16: =(C16-C15)/C15 -> 0.23741007 | N16: =(D16-D15)/D15 -> 0.20446097 | O16: =(E16-E15)/E15 -> 0.18618796 | P16: =C16/D16 -> 1.0617284 | Q16: =E16/D16 -> 23.564722 | R16: =E16/C16 -> 22.19468 | S16: =C16/7 -> 49.142857 | T16: =D16-Y16 -> 305 | U16: =T16/D16 -> 0.94135802 | V16: =Z16/(E16-I16) -> 0.29573397 | W16: 201438 | X16: 2316 | Y16: 19 | Z16: 2257.92 | AA16: 4659.38 | AB16: 0.97 | AC16: =Z16/AA16 -> 0.48459666 | AD16: =X16/W16 -> 0.011497334 | AE16: =Y16/X16 -> 0.0082037997 | AF16: =Z16/Y16 -> 118.83789 | AG16: 84 | AH16: 211 | AI16: 49 | AJ16: =AG16*产品成本!$D$2+AH16*产品成本!$D$3+AI16*产品成本!$D$4 -> 785.42254 | AK16: =AG16*产品成本!$E$2+AH16*产品成本!$E$3+AI16*产品成本!$E$4 -> 65.551711 | AL16: =AG16*产品成本!$F$2+AH16*产品成本!$F$3+AI16*产品成本!$F$4 -> 116.96 | AM16: =AG16*产品成本!$G$2+AH16*产品成本!$G$3+AI16*产品成本!$G$4 -> 1323.96 | AN16: =(E16-I16)*0.15 -> 1145.2455 | AO16: =SUM(AJ16:AN16) -> 3437.1397 | AP16: 13 | AQ16: 16 | AR16: 1 | AS16: =L16/(1-0.15+0.15*0.2) -> 663.43182 | AT16: =AP16*产品成本!$D$2+AQ16*产品成本!$D$3+AR16*产品成本!$D$4 -> 64.577465 | AU16: =AP16*产品成本!$E$2+AQ16*产品成本!$E$3+AR16*产品成本!$E$4 -> 5.5515338 | AV16: =AP16*产品成本!$F$2+AQ16*产品成本!$F$3+AR16*产品成本!$F$4 -> 10.2 | AW16: 0 | AX16: =AS16*0.15 -> 99.514773 | AY16: =-AX16*0.2 -> -19.902955 | AZ16: =SUM(AT16:AY16) -> 159.94082 | BA16: =AO16-AZ16 -> 3277.1989 | BB16: =E16-I16 -> 7634.97 | BC16: =E16-AS16-I16 -> 6971.5382 | BD16: =BC16-BA16-Z16 -> 1436.4193 | BE16: =BD16/BC16 -> 0.20604051 | BG16: 减少广告预算
A17: 0203~0209 | B17: 2025W06 | C17: 351 | D17: 339 | E17: 7769.22 | J17: 23 | K17: =J17/C17 -> 0.065527066 | L17: 440.93 | M17: =(C17-C16)/C16 -> 0.020348837 | N17: =(D17-D16)/D16 -> 0.046296296 | O17: =(E17-E16)/E16 -> 0.017583566 | P17: =C17/D17 -> 1.0353982 | Q17: =E17/D17 -> 22.918053 | R17: =E17/C17 -> 22.13453 | S17: =C17/7 -> 50.142857 | T17: =D17-Y17 -> 118 | U17: =T17/D17 -> 0.3480826 | V17: =Z17/(E17-I17) -> 0.29884853 | W17: 243295 | X17: 2349 | Y17: 221 | Z17: 2321.82 | AA17: 5024.08 | AB17: 0.99 | AC17: =Z17/AA17 -> 0.46213834 | AD17: =X17/W17 -> 0.0096549456 | AE17: =Y17/X17 -> 0.094082588 | AF17: =Z17/Y17 -> 10.505973 | AG17: 105 | AH17: 173 | AI17: 73 | AJ17: =AG17*产品成本!$D$2+AH17*产品成本!$D$3+AI17*产品成本!$D$4 -> 828.94366 | AK17: =AG17*产品成本!$E$2+AH17*产品成本!$E$3+AI17*产品成本!$E$4 -> 66.911434 | AL17: =AG17*产品成本!$F$2+AH17*产品成本!$F$3+AI17*产品成本!$F$4 -> 119.34 | AM17: =AG17*产品成本!$G$2+AH17*产品成本!$G$3+AI17*产品成本!$G$4 -> 1346.85 | AN17: =(E17-I17)*0.15 -> 1165.383 | AO17: =SUM(AJ17:AN17) -> 3527.4281 | AP17: 7 | AQ17: 8 | AR17: 8 | AS17: =L17/(1-0.15+0.15*0.2) -> 501.05682 | AT17: =AP17*产品成本!$D$2+AQ17*产品成本!$D$3+AR17*产品成本!$D$4 -> 58.169014 | AU17: =AP17*产品成本!$E$2+AQ17*产品成本!$E$3+AR17*产品成本!$E$4 -> 4.4375704 | AV17: =AP17*产品成本!$F$2+AQ17*产品成本!$F$3+AR17*产品成本!$F$4 -> 7.82 | AX17: =AS17*0.15 -> 75.158523 | AY17: =-AX17*0.2 -> -15.031705 | AZ17: =SUM(AT17:AY17) -> 130.5534 | BA17: =AO17-AZ17 -> 3396.8747 | BB17: =E17-I17 -> 7769.22 | BC17: =E17-AS17-I17 -> 7268.1632 | BD17: =BC17-BA17-Z17 -> 1549.4685 | BE17: =BD17/BC17 -> 0.2131857 | BG17: 销量5.5FT↑,5FT↓ | BH17: 原价
A18: 0210~0216 | B18: 2025W07 | C18: 399 | D18: 357 | E18: 9260.61 | J18: 29 | K18: =J18/C18 -> 0.072681704 | L18: 585.8 | M18: =(C18-C17)/C17 -> 0.13675214 | N18: =(D18-D17)/D17 -> 0.053097345 | O18: =(E18-E17)/E17 -> 0.19196136 | P18: =C18/D18 -> 1.1176471 | Q18: =E18/D18 -> 25.940084 | R18: =E18/C18 -> 23.209549 | S18: =C18/7 -> 57 | T18: =D18-Y18 -> 138 | U18: =T18/D18 -> 0.38655462 | V18: =Z18/(E18-I18) -> 0.22524866 | W18: 205810 | X18: 2124 | Y18: 219 | Z18: 2085.94 | AA18: 5804.27 | AB18: 0.98 | AC18: =Z18/AA18 -> 0.35938025 | AD18: =X18/W18 -> 0.010320198 | AE18: =Y18/X18 -> 0.10310734 | AF18: =Z18/Y18 -> 9.5248402 | AG18: 139 | AH18: 178 | AI18: 82 | AJ18: =AG18*产品成本!$D$2+AH18*产品成本!$D$3+AI18*产品成本!$D$4 -> 941.12676 | AK18: =AG18*产品成本!$E$2+AH18*产品成本!$E$3+AI18*产品成本!$E$4 -> 75.668024 | AL18: =AG18*产品成本!$F$2+AH18*产品成本!$F$3+AI18*产品成本!$F$4 -> 135.66 | AM18: =AG18*产品成本!$G$2+AH18*产品成本!$G$3+AI18*产品成本!$G$4 -> 1526.91 | AN18: =(E18-I18)*0.15 -> 1389.0915 | AO18: =SUM(AJ18:AN18) -> 4068.4563 | AP18: 6 | AQ18: 14 | AR18: 9 | AS18: =L18/(1-0.15+0.15*0.2) -> 665.68182 | AT18: =AP18*产品成本!$D$2+AQ18*产品成本!$D$3+AR18*产品成本!$D$4 -> 72.042254 | AU18: =AP18*产品成本!$E$2+AQ18*产品成本!$E$3+AR18*产品成本!$E$4 -> 5.6307042 | AV18: =AP18*产品成本!$F$2+AQ18*产品成本!$F$3+AR18*产品成本!$F$4 -> 9.86 | AX18: =AS18*0.15 -> 99.852273 | AY18: =-AX18*0.2 -> -19.970455 | AZ18: =SUM(AT18:AY18) -> 167.41478 | BA18: =AO18-AZ18 -> 3901.0415 | BB18: =E18-I18 -> 9260.61 | BC18: =E18-AS18-I18 -> 8594.9282 | BD18: =BC18-BA18-Z18 -> 2607.9467 | BE18: =BD18/BC18 -> 0.30342856 | BG18: 销量5.5FT↑ | BH18: 原价
A19: 0217~0223 | B19: 2025W08 | C19: 379 | D19: 357 | E19: 9167.51 | J19: 19 | K19: =J19/C19 -> 0.050131926 | L19: 378.87 | M19: =(C19-C18)/C18 -> -0.050125313 | N19: =(D19-D18)/D18 -> 0 | O19: =(E19-E18)/E18 -> -0.010053333 | P19: =C19/D19 -> 1.0616246 | Q19: =E19/D19 -> 25.6793 | R19: =E19/C19 -> 24.188681 | S19: =C19/7 -> 54.142857 | T19: =D19-Y19 -> 119 | U19: =T19/D19 -> 0.33333333 | V19: =Z19/(E19-I19) -> 0.26074256 | W19: 237785 | X19: 2470 | Y19: 238 | Z19: 2390.36 | AA19: 6061.78 | AB19: 0.97 | AC19: =Z19/AA19 -> 0.39433302 | AD19: =X19/W19 -> 0.010387535 | AE19: =Y19/X19 -> 0.096356275 | AF19: =Z19/Y19 -> 10.043529 | AG19: 111 | AH19: 182 | AI19: 86 | AJ19: =AG19*产品成本!$D$2+AH19*产品成本!$D$3+AI19*产品成本!$D$4 -> 903.66197 | AK19: =AG19*产品成本!$E$2+AH19*产品成本!$E$3+AI19*产品成本!$E$4 -> 72.418187 | AL19: =AG19*产品成本!$F$2+AH19*产品成本!$F$3+AI19*产品成本!$F$4 -> 128.86 | AM19: =AG19*产品成本!$G$2+AH19*产品成本!$G$3+AI19*产品成本!$G$4 -> 1454.79 | AN19: =(E19-I19)*0.15 -> 1375.1265 | AO19: =SUM(AJ19:AN19) -> 3934.8567 | AP19: 8 | AQ19: 9 | AR19: 2 | AS19: =L19/(1-0.15+0.15*0.2) -> 430.53409 | AT19: =AP19*产品成本!$D$2+AQ19*产品成本!$D$3+AR19*产品成本!$D$4 -> 42.535211 | AU19: =AP19*产品成本!$E$2+AQ19*产品成本!$E$3+AR19*产品成本!$E$4 -> 3.5439676 | AV19: =AP19*产品成本!$F$2+AQ19*产品成本!$F$3+AR19*产品成本!$F$4 -> 6.46 | AX19: =AS19*0.15 -> 64.580114 | AY19: =-AX19*0.2 -> -12.916023 | AZ19: =SUM(AT19:AY19) -> 104.20327 | BA19: =AO19-AZ19 -> 3830.6534 | BB19: =E19-I19 -> 9167.51 | BC19: =E19-AS19-I19 -> 8736.9759 | BD19: =BC19-BA19-Z19 -> 2515.9625 | BE19: =BD19/BC19 -> 0.2879672 | BG19: 基本保持 | BH19: 原价
A20: 0224~0302 | B20: 2025W09 | C20: 477 | D20: 448 | E20: 11520.55 | J20: 28 | K20: =J20/C20 -> 0.05870021 | L20: 581.9 | M20: =(C20-C19)/C19 -> 0.2585752 | N20: =(D20-D19)/D19 -> 0.25490196 | O20: =(E20-E19)/E19 -> 0.25667166 | P20: =C20/D20 -> 1.0647321 | Q20: =E20/D20 -> 25.715513 | R20: =E20/C20 -> 24.152096 | S20: =C20/7 -> 68.142857 | T20: =D20-Y20 -> 203 | U20: =T20/D20 -> 0.453125 | V20: =Z20/(E20-I20) -> 0.21871091 | W20: 255819 | X20: 2600 | Y20: 245 | Z20: 2519.67 | AA20: 6351.18 | AB20: 0.97 | AC20: =Z20/AA20 -> 0.3967247 | AD20: =X20/W20 -> 0.010163436 | AE20: =Y20/X20 -> 0.094230769 | AF20: =Z20/Y20 -> 10.284367 | AG20: 139 | AH20: 239 | AI20: 99 | AJ20: =AG20*产品成本!$D$2+AH20*产品成本!$D$3+AI20*产品成本!$D$4 -> 1126.2676 | AK20: =AG20*产品成本!$E$2+AH20*产品成本!$E$3+AI20*产品成本!$E$4 -> 90.998223 | AL20: =AG20*产品成本!$F$2+AH20*产品成本!$F$3+AI20*产品成本!$F$4 -> 162.18 | AM20: =AG20*产品成本!$G$2+AH20*产品成本!$G$3+AI20*产品成本!$G$4 -> 1831.11 | AN20: =(E20-I20)*0.15 -> 1728.0825 | AO20: =SUM(AJ20:AN20) -> 4938.6383 | AP20: 8 | AQ20: 15 | AR20: 5 | AS20: =L20/(1-0.15+0.15*0.2) -> 661.25 | AT20: =AP20*产品成本!$D$2+AQ20*产品成本!$D$3+AR20*产品成本!$D$4 -> 65.140845 | AU20: =AP20*产品成本!$E$2+AQ20*产品成本!$E$3+AR20*产品成本!$E$4 -> 5.3307085 | AV20: =AP20*产品成本!$F$2+AQ20*产品成本!$F$3+AR20*产品成本!$F$4 -> 9.52 | AX20: =AS20*0.15 -> 99.1875 | AY20: =-AX20*0.2 -> -19.8375 | AZ20: =SUM(AT20:AY20) -> 159.34155 | BA20: =AO20-AZ20 -> 4779.2968 | BB20: =E20-I20 -> 11520.55 | BC20: =E20-AS20-I20 -> 10859.3 | BD20: =BC20-BA20-Z20 -> 3560.3332 | BE20: =BD20/BC20 -> 0.32786029 | BH20: 原价
A21: 0303~0309 | B21: 2025W10 | C21: 350 | D21: 338 | E21: 8390.83 | J21: 29 | K21: =J21/C21 -> 0.082857143 | L21: 604.6 | M21: =(C21-C20)/C20 -> -0.26624738 | N21: =(D21-D20)/D20 -> -0.24553571 | O21: =(E21-E20)/E20 -> -0.27166411 | P21: =C21/D21 -> 1.035503 | Q21: =E21/D21 -> 24.824941 | R21: =E21/C21 -> 23.9738 | S21: =C21/7 -> 50 | T21: =D21-Y21 -> 123 | U21: =T21/D21 -> 0.36390533 | V21: =Z21/(E21-I21) -> 0.30769662 | W21: 261831 | X21: 2520 | Y21: 215 | Z21: 2581.83 | AA21: 5283.21 | AB21: 1.02 | AC21: =Z21/AA21 -> 0.48868586 | AD21: =X21/W21 -> 0.0096245288 | AE21: =Y21/X21 -> 0.08531746 | AF21: =Z21/Y21 -> 12.008512 | AG21: 99 | AH21: 207 | AI21: 44 | AJ21: =AG21*产品成本!$D$2+AH21*产品成本!$D$3+AI21*产品成本!$D$4 -> 792.11268 | AK21: =AG21*产品成本!$E$2+AH21*产品成本!$E$3+AI21*产品成本!$E$4 -> 66.334656 | AL21: =AG21*产品成本!$F$2+AH21*产品成本!$F$3+AI21*产品成本!$F$4 -> 119 | AM21: =AG21*产品成本!$G$2+AH21*产品成本!$G$3+AI21*产品成本!$G$4 -> 1344.21 | AN21: =(E21-I21)*0.15 -> 1258.6245 | AO21: =SUM(AJ21:AN21) -> 3580.2818 | AP21: 9 | AQ21: 15 | AR21: 5 | AS21: =L21/(1-0.15+0.15*0.2) -> 687.04545 | AT21: =AP21*产品成本!$D$2+AQ21*产品成本!$D$3+AR21*产品成本!$D$4 -> 67.253521 | AU21: =AP21*产品成本!$E$2+AQ21*产品成本!$E$3+AR21*产品成本!$E$4 -> 5.5043155 | AV21: =AP21*产品成本!$F$2+AQ21*产品成本!$F$3+AR21*产品成本!$F$4 -> 9.86 | AX21: =AS21*0.15 -> 103.05682 | AY21: =-AX21*0.2 -> -20.611364 | AZ21: =SUM(AT21:AY21) -> 165.06329 | BA21: =AO21-AZ21 -> 3415.2185 | BB21: =E21-I21 -> 8390.83 | BC21: =E21-AS21-I21 -> 7703.7845 | BD21: =BC21-BA21-Z21 -> 1706.736 | BE21: =BD21/BC21 -> 0.22154514 | BG21: 销量5.5FT黑绿橙断货,其他5.5FT库存28个; CPC↑：断货的5.5FT的平均CPC=0.75 | BH21: 原价
A22: 0310~0316 | B22: 2025W11 | C22: 390 | D22: 376 | E22: 9380.31 | J22: 24 | K22: =J22/C22 -> 0.061538462 | L22: 496.01 | M22: =(C22-C21)/C21 -> 0.11428571 | N22: =(D22-D21)/D21 -> 0.11242604 | O22: =(E22-E21)/E21 -> 0.11792397 | P22: =C22/D22 -> 1.037234 | Q22: =E22/D22 -> 24.947633 | R22: =E22/C22 -> 24.052077 | S22: =C22/7 -> 55.714286 | T22: =D22-Y22 -> 111 | U22: =T22/D22 -> 0.29521277 | V22: =Z22/(E22-I22) -> 0.31517508 | W22: 263574 | X22: 2836 | Y22: 265 | Z22: 2956.44 | AA22: 6504.79 | AB22: 1.04 | AC22: =Z22/AA22 -> 0.45450199 | AD22: =X22/W22 -> 0.010759787 | AE22: =Y22/X22 -> 0.093441467 | AF22: =Z22/Y22 -> 11.156377 | AG22: 121 | AH22: 220 | AI22: 49 | AJ22: =AG22*产品成本!$D$2+AH22*产品成本!$D$3+AI22*产品成本!$D$4 -> 882.60563 | AK22: =AG22*产品成本!$E$2+AH22*产品成本!$E$3+AI22*产品成本!$E$4 -> 73.710283 | AL22: =AG22*产品成本!$F$2+AH22*产品成本!$F$3+AI22*产品成本!$F$4 -> 132.6 | AM22: =AG22*产品成本!$G$2+AH22*产品成本!$G$3+AI22*产品成本!$G$4 -> 1495.59 | AN22: =(E22-I22)*0.15 -> 1407.0465 | AO22: =SUM(AJ22:AN22) -> 3991.5524 | AP22: 9 | AQ22: 12 | AR22: 3 | AS22: =L22/(1-0.15+0.15*0.2) -> 563.64773 | AT22: =AP22*产品成本!$D$2+AQ22*产品成本!$D$3+AR22*产品成本!$D$4 -> 54.295775 | AU22: =AP22*产品成本!$E$2+AQ22*产品成本!$E$3+AR22*产品成本!$E$4 -> 4.5059451 | AV22: =AP22*产品成本!$F$2+AQ22*产品成本!$F$3+AR22*产品成本!$F$4 -> 8.16 | AX22: =AS22*0.15 -> 84.547159 | AY22: =-AX22*0.2 -> -16.909432 | AZ22: =SUM(AT22:AY22) -> 134.59945 | BA22: =AO22-AZ22 -> 3856.953 | BB22: =E22-I22 -> 9380.31 | BC22: =E22-AS22-I22 -> 8816.6623 | BD22: =BC22-BA22-Z22 -> 2003.2693 | BE22: =BD22/BC22 -> 0.22721402 | BG22: 调整广告重心为老款P； 5.5FT短暂有货又马上断货。黑/薄绿/粉共库存26个 | BH22: 原价
A23: 0317~0323 | B23: 2025W12 | C23: 401 | D23: 382 | E23: 9704.49 | J23: 28 | K23: =J23/C23 -> 0.069825436 | L23: 594.58 | M23: =(C23-C22)/C22 -> 0.028205128 | N23: =(D23-D22)/D22 -> 0.015957447 | O23: =(E23-E22)/E22 -> 0.034559625 | P23: =C23/D23 -> 1.0497382 | Q23: =E23/D23 -> 25.404424 | R23: =E23/C23 -> 24.200723 | S23: =C23/7 -> 57.285714 | T23: =D23-Y23 -> 128 | U23: =T23/D23 -> 0.33507853 | V23: =Z23/(E23-I23) -> 0.28675902 | W23: 278481 | X23: 2758 | Y23: 254 | Z23: 2782.85 | AA23: 6199.12 | AB23: 1.01 | AC23: =Z23/AA23 -> 0.44891049 | AD23: =X23/W23 -> 0.0099037277 | AE23: =Y23/X23 -> 0.092095722 | AF23: =Z23/Y23 -> 10.956102 | AG23: 106 | AH23: 264 | AI23: 31 | AJ23: =AG23*产品成本!$D$2+AH23*产品成本!$D$3+AI23*产品成本!$D$4 -> 884.29577 | AK23: =AG23*产品成本!$E$2+AH23*产品成本!$E$3+AI23*产品成本!$E$4 -> 75.808944 | AL23: =AG23*产品成本!$F$2+AH23*产品成本!$F$3+AI23*产品成本!$F$4 -> 136.34 | AM23: =AG23*产品成本!$G$2+AH23*产品成本!$G$3+AI23*产品成本!$G$4 -> 1541.64 | AN23: =(E23-I23)*0.15 -> 1455.6735 | AO23: =SUM(AJ23:AN23) -> 4093.7582 | AP23: 8 | AQ23: 16 | AR23: 4 | AS23: =L23/(1-0.15+0.15*0.2) -> 675.65909 | AT23: =AP23*产品成本!$D$2+AQ23*产品成本!$D$3+AR23*产品成本!$D$4 -> 63.943662 | AU23: =AP23*产品成本!$E$2+AQ23*产品成本!$E$3+AR23*产品成本!$E$4 -> 5.3134986 | AV23: =AP23*产品成本!$F$2+AQ23*产品成本!$F$3+AR23*产品成本!$F$4 -> 9.52 | AX23: =AS23*0.15 -> 101.34886 | AY23: =-AX23*0.2 -> -20.269773 | AZ23: =SUM(AT23:AY23) -> 159.85625 | BA23: =AO23-AZ23 -> 3933.902 | BB23: =E23-I23 -> 9704.49 | BC23: =E23-AS23-I23 -> 9028.8309 | BD23: =BC23-BA23-Z23 -> 2312.0789 | BE23: =BD23/BC23 -> 0.25607733 | BG23: 调整广告重心为老款P； 5.5FT依旧有货 | BH23: 原价
A24: 0324~0330 | B24: 2025W13 | C24: 464 | D24: 441 | E24: 9746.86 | J24: 24 | K24: =J24/C24 -> 0.051724138 | L24: 493.76 | M24: =(C24-C23)/C23 -> 0.15710723 | N24: =(D24-D23)/D23 -> 0.15445026 | O24: =(E24-E23)/E23 -> 0.0043660203 | P24: =C24/D24 -> 1.0521542 | Q24: =E24/D24 -> 22.101723 | R24: =E24/C24 -> 21.006164 | S24: =C24/7 -> 66.285714 | T24: =D24-Y24 -> 164 | U24: =T24/D24 -> 0.37188209 | V24: =Z24/(E24-I24) -> 0.30536809 | W24: 236690 | X24: 2806 | Y24: 277 | Z24: 2976.38 | AA24: 6103.54 | AB24: 1.06 | AC24: =Z24/AA24 -> 0.48764815 | AD24: =X24/W24 -> 0.011855169 | AE24: =Y24/X24 -> 0.098717035 | AF24: =Z24/Y24 -> 10.745054 | AG24: 151 | AH24: 257 | AI24: 56 | AJ24: =AG24*产品成本!$D$2+AH24*产品成本!$D$3+AI24*产品成本!$D$4 -> 1047.3239 | AK24: =AG24*产品成本!$E$2+AH24*产品成本!$E$3+AI24*产品成本!$E$4 -> 87.52173 | AL24: =AG24*产品成本!$F$2+AH24*产品成本!$F$3+AI24*产品成本!$F$4 -> 157.76 | AM24: =AG24*产品成本!$G$2+AH24*产品成本!$G$3+AI24*产品成本!$G$4 -> 1777.89 | AN24: =(E24-I24)*0.15 -> 1462.029 | AO24: =SUM(AJ24:AN24) -> 4532.5247 | AP24: 8 | AQ24: 14 | AR24: 2 | AS24: =L24/(1-0.15+0.15*0.2) -> 561.09091 | AT24: =AP24*产品成本!$D$2+AQ24*产品成本!$D$3+AR24*产品成本!$D$4 -> 53.098592 | AU24: =AP24*产品成本!$E$2+AQ24*产品成本!$E$3+AR24*产品成本!$E$4 -> 4.5079183 | AV24: =AP24*产品成本!$F$2+AQ24*产品成本!$F$3+AR24*产品成本!$F$4 -> 8.16 | AX24: =AS24*0.15 -> 84.163636 | AY24: =-AX24*0.2 -> -16.832727 | AZ24: =SUM(AT24:AY24) -> 133.09742 | BA24: =AO24-AZ24 -> 4399.4273 | BB24: =E24-I24 -> 9746.86 | BC24: =E24-AS24-I24 -> 9185.7691 | BD24: =BC24-BA24-Z24 -> 1809.9618 | BE24: =BD24/BC24 -> 0.19703977 | BG24: 春促15%off折扣，销量提升，但是客单价降低 | BH24: 85折
A25: 0331~0406 | B25: 2025W14 | C25: 486 | D25: 465 | E25: 11015.19 | J25: 31 | K25: =J25/C25 -> 0.063786008 | L25: 630.36 | M25: =(C25-C24)/C24 -> 0.047413793 | N25: =(D25-D24)/D24 -> 0.054421769 | O25: =(E25-E24)/E24 -> 0.13012704 | P25: =C25/D25 -> 1.0451613 | Q25: =E25/D25 -> 23.688581 | R25: =E25/C25 -> 22.665 | S25: =C25/7 -> 69.428571 | T25: =D25-Y25 -> 154 | U25: =T25/D25 -> 0.3311828 | V25: =Z25/(E25-I25) -> 0.28374545 | W25: 303852 | X25: 2994 | Y25: 311 | Z25: 3125.51 | AA25: 7326.12 | AB25: 1.04 | AC25: =Z25/AA25 -> 0.42662555 | AD25: =X25/W25 -> 0.0098534813 | AE25: =Y25/X25 -> 0.10387442 | AF25: =Z25/Y25 -> 10.049871 | AG25: 164 | AH25: 249 | AI25: 73 | AJ25: =AG25*产品成本!$D$2+AH25*产品成本!$D$3+AI25*产品成本!$D$4 -> 1114.1549 | AK25: =AG25*产品成本!$E$2+AH25*产品成本!$E$3+AI25*产品成本!$E$4 -> 91.8063 | AL25: =AG25*产品成本!$F$2+AH25*产品成本!$F$3+AI25*产品成本!$F$4 -> 165.24 | AM25: =AG25*产品成本!$G$2+AH25*产品成本!$G$3+AI25*产品成本!$G$4 -> 1860.96 | AN25: =(E25-I25)*0.15 -> 1652.2785 | AO25: =SUM(AJ25:AN25) -> 4884.4397 | AP25: 9 | AQ25: 19 | AR25: 3 | AS25: =L25/(1-0.15+0.15*0.2) -> 716.31818 | AT25: =AP25*产品成本!$D$2+AQ25*产品成本!$D$3+AR25*产品成本!$D$4 -> 69.084507 | AU25: =AP25*产品成本!$E$2+AQ25*产品成本!$E$3+AR25*产品成本!$E$4 -> 5.8554761 | AV25: =AP25*产品成本!$F$2+AQ25*产品成本!$F$3+AR25*产品成本!$F$4 -> 10.54 | AX25: =AS25*0.15 -> 107.44773 | AY25: =-AX25*0.2 -> -21.489545 | AZ25: =SUM(AT25:AY25) -> 171.43816 | BA25: =AO25-AZ25 -> 4713.0016 | BB25: =E25-I25 -> 11015.19 | BC25: =E25-AS25-I25 -> 10298.872 | BD25: =BC25-BA25-Z25 -> 2460.3603 | BE25: =BD25/BC25 -> 0.23889609 | BH25: 原价
A26: 0407~0413 | B26: 2025W15 | C26: 416 | D26: 391 | E26: 10020.4 | J26: 23 | K26: =J26/C26 -> 0.055288462 | L26: 472.65 | M26: =(C26-C25)/C25 -> -0.14403292 | N26: =(D26-D25)/D25 -> -0.15913978 | O26: =(E26-E25)/E25 -> -0.090310744 | P26: =C26/D26 -> 1.0639386 | Q26: =E26/D26 -> 25.627621 | R26: =E26/C26 -> 24.0875 | S26: =C26/7 -> 59.428571 | T26: =D26-Y26 -> 153 | U26: =T26/D26 -> 0.39130435 | V26: =Z26/(E26-I26) -> 0.27636721 | W26: 258909 | X26: 2637 | Y26: 238 | Z26: 2769.31 | AA26: 5998.55 | AB26: 1.05 | AC26: =Z26/AA26 -> 0.46166324 | AD26: =X26/W26 -> 0.010185046 | AE26: =Y26/X26 -> 0.090254077 | AF26: =Z26/Y26 -> 11.635756 | AG26: 95 | AH26: 228 | AI26: 93 | AJ26: =AG26*产品成本!$D$2+AH26*产品成本!$D$3+AI26*产品成本!$D$4 -> 990.21127 | AK26: =AG26*产品成本!$E$2+AH26*产品成本!$E$3+AI26*产品成本!$E$4 -> 79.978821 | AL26: =AG26*产品成本!$F$2+AH26*产品成本!$F$3+AI26*产品成本!$F$4 -> 141.44 | AM26: =AG26*产品成本!$G$2+AH26*产品成本!$G$3+AI26*产品成本!$G$4 -> 1602.45 | AN26: =(E26-I26)*0.15 -> 1503.06 | AO26: =SUM(AJ26:AN26) -> 4317.1401 | AP26: 7 | AQ26: 14 | AR26: 2 | AS26: =L26/(1-0.15+0.15*0.2) -> 537.10227 | AT26: =AP26*产品成本!$D$2+AQ26*产品成本!$D$3+AR26*产品成本!$D$4 -> 50.985915 | AU26: =AP26*产品成本!$E$2+AQ26*产品成本!$E$3+AR26*产品成本!$E$4 -> 4.3343113 | AV26: =AP26*产品成本!$F$2+AQ26*产品成本!$F$3+AR26*产品成本!$F$4 -> 7.82 | AX26: =AS26*0.15 -> 80.565341 | AY26: =-AX26*0.2 -> -16.113068 | AZ26: =SUM(AT26:AY26) -> 127.5925 | BA26: =AO26-AZ26 -> 4189.5476 | BB26: =E26-I26 -> 10020.4 | BC26: =E26-AS26-I26 -> 9483.2977 | BD26: =BC26-BA26-Z26 -> 2524.4401 | BE26: =BD26/BC26 -> 0.26619855 | BG26: 主力Black出现断货 | BH26: 原价
A27: 0414~0420 | B27: 2025W16 | C27: 348 | D27: 338 | E27: 8556.44 | J27: 28 | K27: =J27/C27 -> 0.08045977 | L27: 570.05 | M27: =(C27-C26)/C26 -> -0.16346154 | N27: =(D27-D26)/D26 -> -0.13554987 | O27: =(E27-E26)/E26 -> -0.14609796 | P27: =C27/D27 -> 1.0295858 | Q27: =E27/D27 -> 25.314911 | R27: =E27/C27 -> 24.587471 | S27: =C27/7 -> 49.714286 | T27: =D27-Y27 -> 152 | U27: =T27/D27 -> 0.44970414 | V27: =Z27/(E27-I27) -> 0.27541594 | W27: 235160 | X27: 2259 | Y27: 186 | Z27: 2356.58 | AA27: 4686.72 | AB27: 1.04 | AC27: =Z27/AA27 -> 0.50282074 | AD27: =X27/W27 -> 0.0096062255 | AE27: =Y27/X27 -> 0.082337317 | AF27: =Z27/Y27 -> 12.669785 | AG27: 56 | AH27: 188 | AI27: 104 | AJ27: =AG27*产品成本!$D$2+AH27*产品成本!$D$3+AI27*产品成本!$D$4 -> 859.71831 | AK27: =AG27*产品成本!$E$2+AH27*产品成本!$E$3+AI27*产品成本!$E$4 -> 67.806541 | AL27: =AG27*产品成本!$F$2+AH27*产品成本!$F$3+AI27*产品成本!$F$4 -> 118.32 | AM27: =AG27*产品成本!$G$2+AH27*产品成本!$G$3+AI27*产品成本!$G$4 -> 1345.44 | AN27: =(E27-I27)*0.15 -> 1283.466 | AO27: =SUM(AJ27:AN27) -> 3674.7509 | AP27: 9 | AQ27: 13 | AR27: 6 | AS27: =L27/(1-0.15+0.15*0.2) -> 647.78409 | AT27: =AP27*产品成本!$D$2+AQ27*产品成本!$D$3+AR27*产品成本!$D$4 -> 66.338028 | AU27: =AP27*产品成本!$E$2+AQ27*产品成本!$E$3+AR27*产品成本!$E$4 -> 5.3287352 | AV27: =AP27*产品成本!$F$2+AQ27*产品成本!$F$3+AR27*产品成本!$F$4 -> 9.52 | AX27: =AS27*0.15 -> 97.167614 | AY27: =-AX27*0.2 -> -19.433523 | AZ27: =SUM(AT27:AY27) -> 158.92085 | BA27: =AO27-AZ27 -> 3515.83 | BB27: =E27-I27 -> 8556.44 | BC27: =E27-AS27-I27 -> 7908.6559 | BD27: =BC27-BA27-Z27 -> 2036.2459 | BE27: =BD27/BC27 -> 0.25747054 | BG27: 主力Black 3.6FT断货数天 | BH27: 原价
A28: 0421~0427 | B28: 2025W17 | C28: 390 | D28: 356 | E28: 8924.45 | J28: 29 | K28: =J28/C28 -> 0.074358974 | L28: 602.16 | M28: =(C28-C27)/C27 -> 0.12068966 | N28: =(D28-D27)/D27 -> 0.053254438 | O28: =(E28-E27)/E27 -> 0.04300971 | P28: =C28/D28 -> 1.0955056 | Q28: =E28/D28 -> 25.06868 | R28: =E28/C28 -> 22.883205 | S28: =C28/7 -> 55.714286 | T28: =D28-Y28 -> 156 | U28: =T28/D28 -> 0.43820225 | V28: =Z28/(E28-I28) -> 0.28585291 | W28: 246122 | X28: 2473 | Y28: 200 | Z28: 2551.08 | AA28: 4818.21 | AB28: 1.03 | AC28: =Z28/AA28 -> 0.52946634 | AD28: =X28/W28 -> 0.010047862 | AE28: =Y28/X28 -> 0.080873433 | AF28: =Z28/Y28 -> 12.7554 | AG28: 102 | AH28: 186 | AI28: 102 | AJ28: =AG28*产品成本!$D$2+AH28*产品成本!$D$3+AI28*产品成本!$D$4 -> 946.05634 | AK28: =AG28*产品成本!$E$2+AH28*产品成本!$E$3+AI28*产品成本!$E$4 -> 74.986885 | AL28: =AG28*产品成本!$F$2+AH28*产品成本!$F$3+AI28*产品成本!$F$4 -> 132.6 | AM28: =AG28*产品成本!$G$2+AH28*产品成本!$G$3+AI28*产品成本!$G$4 -> 1499.58 | AN28: =(E28-I28)*0.15 -> 1338.6675 | AO28: =SUM(AJ28:AN28) -> 3991.8907 | AP28: 12 | AQ28: 9 | AR28: 8 | AS28: =L28/(1-0.15+0.15*0.2) -> 684.27273 | AT28: =AP28*产品成本!$D$2+AQ28*产品成本!$D$3+AR28*产品成本!$D$4 -> 70.84507 | AU28: =AP28*产品成本!$E$2+AQ28*产品成本!$E$3+AR28*产品成本!$E$4 -> 5.4983958 | AV28: =AP28*产品成本!$F$2+AQ28*产品成本!$F$3+AR28*产品成本!$F$4 -> 9.86 | AX28: =AS28*0.15 -> 102.64091 | AY28: =-AX28*0.2 -> -20.528182 | AZ28: =SUM(AT28:AY28) -> 168.31619 | BA28: =AO28-AZ28 -> 3823.5745 | BB28: =E28-I28 -> 8924.45 | BC28: =E28-AS28-I28 -> 8240.1773 | BD28: =BC28-BA28-Z28 -> 1865.5227 | BE28: =BD28/BC28 -> 0.22639352 | BH28: 后面三天9折
A29: 0428~0504 | B29: 2025W18 | C29: 414 | D29: 390 | E29: 9670.56 | J29: 34 | K29: =J29/C29 -> 0.082125604 | L29: 698.13 | M29: =(C29-C28)/C28 -> 0.061538462 | N29: =(D29-D28)/D28 -> 0.095505618 | O29: =(E29-E28)/E28 -> 0.083602911 | P29: =C29/D29 -> 1.0615385 | Q29: =E29/D29 -> 24.796308 | R29: =E29/C29 -> 23.358841 | S29: =C29/7 -> 59.142857 | T29: =D29-Y29 -> 154 | U29: =T29/D29 -> 0.39487179 | V29: =Z29/(E29-I29) -> 0.25833974 | W29: 224859 | X29: 2444 | Y29: 236 | Z29: 2498.29 | AA29: 5740.71 | AB29: 1.02 | AC29: =Z29/AA29 -> 0.43518833 | AD29: =X29/W29 -> 0.010869033 | AE29: =Y29/X29 -> 0.096563011 | AF29: =Z29/Y29 -> 10.585975 | AG29: 110 | AH29: 217 | AI29: 87 | AJ29: =AG29*产品成本!$D$2+AH29*产品成本!$D$3+AI29*产品成本!$D$4 -> 978.80282 | AK29: =AG29*产品成本!$E$2+AH29*产品成本!$E$3+AI29*产品成本!$E$4 -> 79.202235 | AL29: =AG29*产品成本!$F$2+AH29*产品成本!$F$3+AI29*产品成本!$F$4 -> 140.76 | AM29: =AG29*产品成本!$G$2+AH29*产品成本!$G$3+AI29*产品成本!$G$4 -> 1591.5 | AN29: =(E29-I29)*0.15 -> 1450.584 | AO29: =SUM(AJ29:AN29) -> 4240.8491 | AP29: 8 | AQ29: 17 | AR29: 9 | AS29: =L29/(1-0.15+0.15*0.2) -> 793.32955 | AT29: =AP29*产品成本!$D$2+AQ29*产品成本!$D$3+AR29*产品成本!$D$4 -> 82.605634 | AU29: =AP29*产品成本!$E$2+AQ29*产品成本!$E$3+AR29*产品成本!$E$4 -> 6.5562887 | AV29: =AP29*产品成本!$F$2+AQ29*产品成本!$F$3+AR29*产品成本!$F$4 -> 11.56 | AX29: =AS29*0.15 -> 118.99943 | AY29: =-AX29*0.2 -> -23.799886 | AZ29: =SUM(AT29:AY29) -> 195.92147 | BA29: =AO29-AZ29 -> 4044.9276 | BB29: =E29-I29 -> 9670.56 | BC29: =E29-AS29-I29 -> 8877.2305 | BD29: =BC29-BA29-Z29 -> 2334.0129 | BE29: =BD29/BC29 -> 0.26292129 | BG29: 5.5FT多巴胺出现断货 | BH29: 后面三天9折
A30: 0505~0511 | B30: 2025W19 | C30: 463 | D30: 435 | E30: 11347.24 | J30: 33 | K30: =J30/C30 -> 0.071274298 | L30: 661.95 | M30: =(C30-C29)/C29 -> 0.11835749 | N30: =(D30-D29)/D29 -> 0.11538462 | O30: =(E30-E29)/E29 -> 0.17337982 | P30: =C30/D30 -> 1.0643678 | Q30: =E30/D30 -> 26.085609 | R30: =E30/C30 -> 24.508078 | S30: =C30/7 -> 66.142857 | T30: =D30-Y30 -> 151 | U30: =T30/D30 -> 0.34712644 | V30: =Z30/(E30-I30) -> 0.24144373 | W30: 250034 | X30: 2650 | Y30: 284 | Z30: 2739.72 | AA30: 7513.18 | AB30: 1.03 | AC30: =Z30/AA30 -> 0.36465518 | AD30: =X30/W30 -> 0.010598559 | AE30: =Y30/X30 -> 0.10716981 | AF30: =Z30/Y30 -> 9.6469014 | AG30: 125 | AH30: 229 | AI30: 109 | AJ30: =AG30*产品成本!$D$2+AH30*产品成本!$D$3+AI30*产品成本!$D$4 -> 1108.662 | AK30: =AG30*产品成本!$E$2+AH30*产品成本!$E$3+AI30*产品成本!$E$4 -> 88.739823 | AL30: =AG30*产品成本!$F$2+AH30*产品成本!$F$3+AI30*产品成本!$F$4 -> 157.42 | AM30: =AG30*产品成本!$G$2+AH30*产品成本!$G$3+AI30*产品成本!$G$4 -> 1779.45 | AN30: =(E30-I30)*0.15 -> 1702.086 | AO30: =SUM(AJ30:AN30) -> 4836.3578 | AP30: 11 | AQ30: 17 | AR30: 5 | AS30: =L30/(1-0.15+0.15*0.2) -> 752.21591 | AT30: =AP30*产品成本!$D$2+AQ30*产品成本!$D$3+AR30*产品成本!$D$4 -> 75.704225 | AU30: =AP30*产品成本!$E$2+AQ30*产品成本!$E$3+AR30*产品成本!$E$4 -> 6.2371099 | AV30: =AP30*产品成本!$F$2+AQ30*产品成本!$F$3+AR30*产品成本!$F$4 -> 11.22 | AX30: =AS30*0.15 -> 112.83239 | AY30: =-AX30*0.2 -> -22.566477 | AZ30: =SUM(AT30:AY30) -> 183.42724 | BA30: =AO30-AZ30 -> 4652.9306 | BB30: =E30-I30 -> 11347.24 | BC30: =E30-AS30-I30 -> 10595.024 | BD30: =BC30-BA30-Z30 -> 3202.3735 | BE30: =BD30/BC30 -> 0.3022526
A31: 0512~0518 | B31: 2025W20 | C31: 373 | D31: 360 | E31: 9134.48 | F31: 29 | G31: 29 | H31: 721.31 | I31: 63.1 | J31: 23 | K31: =J31/C31 -> 0.061662198 | L31: 487.61 | M31: =(C31-C30)/C30 -> -0.19438445 | N31: =(D31-D30)/D30 -> -0.17241379 | O31: =(E31-E30)/E30 -> -0.19500425 | P31: =C31/D31 -> 1.0361111 | Q31: =E31/D31 -> 25.373556 | R31: =E31/C31 -> 24.489223 | S31: =C31/7 -> 53.285714 | T31: =D31-Y31 -> 147 | U31: =T31/D31 -> 0.40833333 | V31: =Z31/(E31-I31) -> 0.27482037 | W31: 329751 | X31: 2477 | Y31: 213 | Z31: 2493 | AA31: 5394.2 | AB31: 1.01 | AC31: =Z31/AA31 -> 0.46216306 | AD31: =X31/W31 -> 0.0075117285 | AE31: =Y31/X31 -> 0.085991118 | AF31: =Z31/Y31 -> 11.704225 | AG31: 84 | AH31: 170 | AI31: 119 | AJ31: =AG31*产品成本!$D$2+AH31*产品成本!$D$3+AI31*产品成本!$D$4 -> 930.49296 | AK31: =AG31*产品成本!$E$2+AH31*产品成本!$E$3+AI31*产品成本!$E$4 -> 72.347315 | AL31: =AG31*产品成本!$F$2+AH31*产品成本!$F$3+AI31*产品成本!$F$4 -> 126.82 | AM31: =AG31*产品成本!$G$2+AH31*产品成本!$G$3+AI31*产品成本!$G$4 -> 1437.06 | AN31: =(E31-I31)*0.15 -> 1360.707 | AO31: =SUM(AJ31:AN31) -> 3927.4273 | AP31: 5 | AQ31: 12 | AR31: 6 | AS31: =L31/(1-0.15+0.15*0.2) -> 554.10227 | AT31: =AP31*产品成本!$D$2+AQ31*产品成本!$D$3+AR31*产品成本!$D$4 -> 55.774648 | AU31: =AP31*产品成本!$E$2+AQ31*产品成本!$E$3+AR31*产品成本!$E$4 -> 4.4415169 | AV31: =AP31*产品成本!$F$2+AQ31*产品成本!$F$3+AR31*产品成本!$F$4 -> 7.82 | AX31: =AS31*0.15 -> 83.115341 | AY31: =-AX31*0.2 -> -16.623068 | AZ31: =SUM(AT31:AY31) -> 134.52844 | BA31: =AO31-AZ31 -> 3792.8988 | BB31: =E31-I31 -> 9071.38 | BC31: =E31-AS31-I31 -> 8517.2777 | BD31: =BC31-BA31-Z31 -> 2231.3789 | BE31: =BD31/BC31 -> 0.26198264 | BG31: 粉色三尺寸彻底断货上周销量20+,粉色SKU的流量切断 | BH31: 原价
A32: 0519~0525 | B32: 2025W21 | C32: 415 | D32: 392 | E32: 10098.35 | F32: 96 | G32: 90 | H32: 2303.24 | I32: 288.75 | J32: 27 | K32: =J32/C32 -> 0.065060241 | L32: 574.62 | M32: =(C32-C31)/C31 -> 0.11260054 | N32: =(D32-D31)/D31 -> 0.088888889 | O32: =(E32-E31)/E31 -> 0.10551996 | P32: =C32/D32 -> 1.0586735 | Q32: =E32/D32 -> 25.761097 | R32: =E32/C32 -> 24.333373 | S32: =C32/7 -> 59.285714 | T32: =D32-Y32 -> 150 | U32: =T32/D32 -> 0.38265306 | V32: =Z32/(E32-I32) -> 0.28468949 | W32: 550872 | X32: 2687 | Y32: 242 | Z32: 2792.69 | AA32: 6031.52 | AB32: 1.04 | AC32: =Z32/AA32 -> 0.46301596 | AD32: =X32/W32 -> 0.0048777211 | AE32: =Y32/X32 -> 0.090063268 | AF32: =Z32/Y32 -> 11.540041 | AG32: 120 | AH32: 178 | AI32: 117 | AJ32: =AG32*产品成本!$D$2+AH32*产品成本!$D$3+AI32*产品成本!$D$4 -> 1016.831 | AK32: =AG32*产品成本!$E$2+AH32*产品成本!$E$3+AI32*产品成本!$E$4 -> 79.71949 | AL32: =AG32*产品成本!$F$2+AH32*产品成本!$F$3+AI32*产品成本!$F$4 -> 141.1 | AM32: =AG32*产品成本!$G$2+AH32*产品成本!$G$3+AI32*产品成本!$G$4 -> 1593.3 | AN32: =(E32-I32)*0.15 -> 1471.44 | AO32: =SUM(AJ32:AN32) -> 4302.3905 | AP32: 5 | AQ32: 13 | AR32: 9 | AS32: =L32/(1-0.15+0.15*0.2) -> 652.97727 | AT32: =AP32*产品成本!$D$2+AQ32*产品成本!$D$3+AR32*产品成本!$D$4 -> 67.816901 | AU32: =AP32*产品成本!$E$2+AQ32*产品成本!$E$3+AR32*产品成本!$E$4 -> 5.264307 | AV32: =AP32*产品成本!$F$2+AQ32*产品成本!$F$3+AR32*产品成本!$F$4 -> 9.18 | AX32: =AS32*0.15 -> 97.946591 | AY32: =-AX32*0.2 -> -19.589318 | AZ32: =SUM(AT32:AY32) -> 160.61848 | BA32: =AO32-AZ32 -> 4141.772 | BB32: =E32-I32 -> 9809.6 | BC32: =E32-AS32-I32 -> 9156.6227 | BD32: =BC32-BA32-Z32 -> 2222.1607 | BE32: =BD32/BC32 -> 0.24268344 | BG32: 本周五促销LD,85折
A33: 0526~0601 | B33: 2025W22 | C33: 400 | D33: 382 | E33: 9152.47 | F33: 27 | G33: 26 | H33: 611.41 | I33: 57.15 | J33: 39 | K33: =J33/C33 -> 0.0975 | L33: 806.14 | M33: =(C33-C32)/C32 -> -0.036144578 | N33: =(D33-D32)/D32 -> -0.025510204 | O33: =(E33-E32)/E32 -> -0.093666787 | P33: =C33/D33 -> 1.0471204 | Q33: =E33/D33 -> 23.959346 | R33: =E33/C33 -> 22.881175 | S33: =C33/7 -> 57.142857 | T33: =D33-Y33 -> 144 | U33: =T33/D33 -> 0.37696335 | V33: =Z33/(E33-I33) -> 0.31048165 | W33: 261666 | X33: 2721 | Y33: 238 | Z33: 2823.93 | AA33: 5786.5 | AB33: 1.04 | AC33: =Z33/AA33 -> 0.48802039 | AD33: =X33/W33 -> 0.010398753 | AE33: =Y33/X33 -> 0.087467843 | AF33: =Z33/Y33 -> 11.865252 | AG33: 117 | AH33: 172 | AI33: 111 | AJ33: =AG33*产品成本!$D$2+AH33*产品成本!$D$3+AI33*产品成本!$D$4 -> 977.95775 | AK33: =AG33*产品成本!$E$2+AH33*产品成本!$E$3+AI33*产品成本!$E$4 -> 76.781928 | AL33: =AG33*产品成本!$F$2+AH33*产品成本!$F$3+AI33*产品成本!$F$4 -> 136 | AM33: =AG33*产品成本!$G$2+AH33*产品成本!$G$3+AI33*产品成本!$G$4 -> 1535.43 | AN33: =(E33-I33)*0.15 -> 1364.298 | AO33: =SUM(AJ33:AN33) -> 4090.4677 | AP33: 12 | AQ33: 16 | AR33: 11 | AS33: =L33/(1-0.15+0.15*0.2) -> 916.06818 | AT33: =AP33*产品成本!$D$2+AQ33*产品成本!$D$3+AR33*产品成本!$D$4 -> 95.56338 | AU33: =AP33*产品成本!$E$2+AQ33*产品成本!$E$3+AR33*产品成本!$E$4 -> 7.4779268 | AV33: =AP33*产品成本!$F$2+AQ33*产品成本!$F$3+AR33*产品成本!$F$4 -> 13.26 | AX33: =AS33*0.15 -> 137.41023 | AY33: =-AX33*0.2 -> -27.482045 | AZ33: =SUM(AT33:AY33) -> 226.22949 | BA33: =AO33-AZ33 -> 3864.2382 | BB33: =E33-I33 -> 9095.32 | BC33: =E33-AS33-I33 -> 8179.2518 | BD33: =BC33-BA33-Z33 -> 1491.0836 | BE33: =BD33/BC33 -> 0.18230074 | BG33: 上周测试了SB SD广告开头效果不佳，退货略高 | BH33: 9折
A34: 0602~0608 | B34: 2025W23 | C34: 429 | D34: 395 | E34: 10442.62 | F34: 49 | G34: 41 | H34: 1233.71 | I34: 75.81 | J34: 43 | K34: =J34/C34 -> 0.1002331 | L34: 911.89 | M34: =(C34-C33)/C33 -> 0.0725 | N34: =(D34-D33)/D33 -> 0.034031414 | O34: =(E34-E33)/E33 -> 0.14096195 | P34: =C34/D34 -> 1.0860759 | Q34: =E34/D34 -> 26.437013 | R34: =E34/C34 -> 24.341772 | S34: =C34/7 -> 61.285714 | T34: =D34-Y34 -> 141 | U34: =T34/D34 -> 0.35696203 | V34: =Z34/(E34-I34) -> 0.25956683 | W34: 238222 | X34: 2771 | Y34: 254 | Z34: 2690.88 | AA34: 6334.77 | AB34: 0.97 | AC34: =Z34/AA34 -> 0.42477943 | AD34: =X34/W34 -> 0.011632007 | AE34: =Y34/X34 -> 0.091663659 | AF34: =Z34/Y34 -> 10.594016 | AG34: 108 | AH34: 221 | AI34: 100 | AJ34: =AG34*产品成本!$D$2+AH34*产品成本!$D$3+AI34*产品成本!$D$4 -> 1026.0563 | AK34: =AG34*产品成本!$E$2+AH34*产品成本!$E$3+AI34*产品成本!$E$4 -> 82.356182 | AL34: =AG34*产品成本!$F$2+AH34*产品成本!$F$3+AI34*产品成本!$F$4 -> 145.86 | AM34: =AG34*产品成本!$G$2+AH34*产品成本!$G$3+AI34*产品成本!$G$4 -> 1650.42 | AN34: =(E34-I34)*0.15 -> 1555.0215 | AO34: =SUM(AJ34:AN34) -> 4459.714 | AP34: 7 | AQ34: 20 | AR34: 16 | AS34: =L34/(1-0.15+0.15*0.2) -> 1036.2386 | AT34: =AP34*产品成本!$D$2+AQ34*产品成本!$D$3+AR34*产品成本!$D$4 -> 110 | AU34: =AP34*产品成本!$E$2+AQ34*产品成本!$E$3+AR34*产品成本!$E$4 -> 8.4310521 | AV34: =AP34*产品成本!$F$2+AQ34*产品成本!$F$3+AR34*产品成本!$F$4 -> 14.62 | AX34: =AS34*0.15 -> 155.4358 | AY34: =-AX34*0.2 -> -31.087159 | AZ34: =SUM(AT34:AY34) -> 257.39969 | BA34: =AO34-AZ34 -> 4202.3143 | BB34: =E34-I34 -> 10366.81 | BC34: =E34-AS34-I34 -> 9330.5714 | BD34: =BC34-BA34-Z34 -> 2437.377 | BE34: =BD34/BC34 -> 0.26122484
A35: 0609~0615 | B35: 2025W24 | C35: 411 | D35: 383 | E35: 10097.4 | F35: 59 | G35: 59 | H35: 1913.42 | I35: 245.79 | J35: 16 | K35: =J35/C35 -> 0.03892944 | L35: 317.88 | M35: =(C35-C34)/C34 -> -0.041958042 | N35: =(D35-D34)/D34 -> -0.030379747 | O35: =(E35-E34)/E34 -> -0.033058753 | P35: =C35/D35 -> 1.073107 | Q35: =E35/D35 -> 26.363969 | R35: =E35/C35 -> 24.567883 | S35: =C35/7 -> 58.714286 | T35: =D35-Y35 -> 143 | U35: =T35/D35 -> 0.37336815 | V35: =Z35/(E35-I35) -> 0.29860398 | W35: 309763 | X35: 3025 | Y35: 240 | Z35: 2941.73 | AA35: 6135.47 | AB35: 0.97 | AC35: =Z35/AA35 -> 0.47946286 | AD35: =X35/W35 -> 0.0097655304 | AE35: =Y35/X35 -> 0.079338843 | AF35: =Z35/Y35 -> 12.257208 | AG35: 90 | AH35: 194 | AI35: 150 | AJ35: =AG35*产品成本!$D$2+AH35*产品成本!$D$3+AI35*产品成本!$D$4 -> 1096.4789 | AK35: =AG35*产品成本!$E$2+AH35*产品成本!$E$3+AI35*产品成本!$E$4 -> 84.525921 | AL35: =AG35*产品成本!$F$2+AH35*产品成本!$F$3+AI35*产品成本!$F$4 -> 147.56 | AM35: =AG35*产品成本!$G$2+AH35*产品成本!$G$3+AI35*产品成本!$G$4 -> 1673.7 | AN35: =(E35-I35)*0.15 -> 1477.7415 | AO35: =SUM(AJ35:AN35) -> 4480.0063 | AP35: 9 | AQ35: 5 | AR35: 2 | AS35: =L35/(1-0.15+0.15*0.2) -> 361.22727 | AT35: =AP35*产品成本!$D$2+AQ35*产品成本!$D$3+AR35*产品成本!$D$4 -> 36.197183 | AU35: =AP35*产品成本!$E$2+AQ35*产品成本!$E$3+AR35*产品成本!$E$4 -> 2.9464141 | AV35: =AP35*产品成本!$F$2+AQ35*产品成本!$F$3+AR35*产品成本!$F$4 -> 5.44 | AX35: =AS35*0.15 -> 54.184091 | AY35: =-AX35*0.2 -> -10.836818 | AZ35: =SUM(AT35:AY35) -> 87.93087 | BA35: =AO35-AZ35 -> 4392.0754 | BB35: =E35-I35 -> 9851.61 | BC35: =E35-AS35-I35 -> 9490.3827 | BD35: =BC35-BA35-Z35 -> 2156.5773 | BE35: =BD35/BC35 -> 0.22723818
A36: 0616~0622 | B36: 2025W25 | C36: 403 | D36: 379 | E36: 9785.09 | F36: 41 | G36: 39 | H36: 1009.39 | I36: 91.31 | J36: 29 | K36: =J36/C36 -> 0.071960298 | L36: 595.28 | M36: =(C36-C35)/C35 -> -0.01946472 | N36: =(D36-D35)/D35 -> -0.010443864 | O36: =(E36-E35)/E35 -> -0.030929744 | P36: =C36/D36 -> 1.0633245 | Q36: =E36/D36 -> 25.818179 | R36: =E36/C36 -> 24.28062 | S36: =C36/7 -> 57.571429 | T36: =D36-Y36 -> 129 | U36: =T36/D36 -> 0.34036939 | V36: =Z36/(E36-I36) -> 0.29276299 | W36: 259867 | X36: 2668 | Y36: 250 | Z36: 2837.98 | AA36: 6226.65 | AB36: 1.06 | AC36: =Z36/AA36 -> 0.45577959 | AD36: =X36/W36 -> 0.01026679 | AE36: =Y36/X36 -> 0.093703148 | AF36: =Z36/Y36 -> 11.35192 | AG36: 114 | AH36: 160 | AI36: 129 | AJ36: =AG36*产品成本!$D$2+AH36*产品成本!$D$3+AI36*产品成本!$D$4 -> 1005.8451 | AK36: =AG36*产品成本!$E$2+AH36*产品成本!$E$3+AI36*产品成本!$E$4 -> 77.727625 | AL36: =AG36*产品成本!$F$2+AH36*产品成本!$F$3+AI36*产品成本!$F$4 -> 137.02 | AM36: =AG36*产品成本!$G$2+AH36*产品成本!$G$3+AI36*产品成本!$G$4 -> 1547.76 | AN36: =(E36-I36)*0.15 -> 1454.067 | AO36: =SUM(AJ36:AN36) -> 4222.4197 | AP36: 8 | AQ36: 16 | AR36: 5 | AS36: =L36/(1-0.15+0.15*0.2) -> 676.45455 | AT36: =AP36*产品成本!$D$2+AQ36*产品成本!$D$3+AR36*产品成本!$D$4 -> 67.253521 | AU36: =AP36*产品成本!$E$2+AQ36*产品成本!$E$3+AR36*产品成本!$E$4 -> 5.5234986 | AV36: =AP36*产品成本!$F$2+AQ36*产品成本!$F$3+AR36*产品成本!$F$4 -> 9.86 | AX36: =AS36*0.15 -> 101.46818 | AY36: =-AX36*0.2 -> -20.293636 | AZ36: =SUM(AT36:AY36) -> 163.81157 | BA36: =AO36-AZ36 -> 4058.6081 | BB36: =E36-I36 -> 9693.78 | BC36: =E36-AS36-I36 -> 9017.3255 | BD36: =BC36-BA36-Z36 -> 2120.7373 | BE36: =BD36/BC36 -> 0.23518474
A37: 0623~0629 | B37: 2025W26 | C37: 419 | D37: 402 | E37: 9316.53 | F37: 56 | G37: 55 | H37: 1311.09 | I37: 158.54 | J37: 21 | K37: =J37/C37 -> 0.050119332 | L37: 426.53 | M37: =(C37-C36)/C36 -> 0.039702233 | N37: =(D37-D36)/D36 -> 0.060686016 | O37: =(E37-E36)/E36 -> -0.047885099 | P37: =C37/D37 -> 1.0422886 | Q37: =E37/D37 -> 23.175448 | R37: =E37/C37 -> 22.235155 | S37: =C37/7 -> 59.857143 | T37: =D37-Y37 -> 139 | U37: =T37/D37 -> 0.34577114 | V37: =Z37/(E37-I37) -> 0.30174853 | W37: 254466 | X37: 2593 | Y37: 263 | Z37: 2763.41 | AA37: 5980.15 | AB37: 1.07 | AC37: =Z37/AA37 -> 0.4620971 | AD37: =X37/W37 -> 0.010189966 | AE37: =Y37/X37 -> 0.10142692 | AF37: =Z37/Y37 -> 10.507262 | AG37: 119 | AH37: 144 | AI37: 156 | AJ37: =AG37*产品成本!$D$2+AH37*产品成本!$D$3+AI37*产品成本!$D$4 -> 1071.9718 | AK37: =AG37*产品成本!$E$2+AH37*产品成本!$E$3+AI37*产品成本!$E$4 -> 81.181018 | AL37: =AG37*产品成本!$F$2+AH37*产品成本!$F$3+AI37*产品成本!$F$4 -> 142.46 | AM37: =AG37*产品成本!$G$2+AH37*产品成本!$G$3+AI37*产品成本!$G$4 -> 1609.11 | AN37: =(E37-I37)*0.15 -> 1373.6985 | AO37: =SUM(AJ37:AN37) -> 4278.4213 | AP37: 7 | AQ37: 7 | AR37: 7 | AS37: =L37/(1-0.15+0.15*0.2) -> 484.69318 | AT37: =AP37*产品成本!$D$2+AQ37*产品成本!$D$3+AR37*产品成本!$D$4 -> 52.746479 | AU37: =AP37*产品成本!$E$2+AQ37*产品成本!$E$3+AR37*产品成本!$E$4 -> 4.0347803 | AV37: =AP37*产品成本!$F$2+AQ37*产品成本!$F$3+AR37*产品成本!$F$4 -> 7.14 | AX37: =AS37*0.15 -> 72.703977 | AY37: =-AX37*0.2 -> -14.540795 | AZ37: =SUM(AT37:AY37) -> 122.08444 | BA37: =AO37-AZ37 -> 4156.3369 | BB37: =E37-I37 -> 9157.99 | BC37: =E37-AS37-I37 -> 8673.2968 | BD37: =BC37-BA37-Z37 -> 1753.5499 | BE37: =BD37/BC37 -> 0.20217801
A38: 0630~0706 | B38: 2025W27 | C38: 392 | D38: 375 | E38: 8810.43 | F38: 19 | G38: 16 | H38: 425.76 | I38: 36.29 | J38: 25 | K38: =J38/C38 -> 0.06377551 | L38: 431.32 | M38: =(C38-C37)/C37 -> -0.064439141 | N38: =(D38-D37)/D37 -> -0.067164179 | O38: =(E38-E37)/E37 -> -0.0543228 | P38: =C38/D38 -> 1.0453333 | Q38: =E38/D38 -> 23.49448 | R38: =E38/C38 -> 22.475587 | S38: =C38/7 -> 56 | T38: =D38-Y38 -> 90 | U38: =T38/D38 -> 0.24 | V38: =Z38/(E38-I38) -> 0.32948756 | W38: 231377 | X38: 2629 | Y38: 285 | Z38: 2890.97 | AA38: 6529.11 | AB38: 1.1 | AC38: =Z38/AA38 -> 0.44278163 | AD38: =X38/W38 -> 0.011362409 | AE38: =Y38/X38 -> 0.10840624 | AF38: =Z38/Y38 -> 10.143754 | AG38: 106 | AH38: 129 | AI38: 157 | AJ38: =AG38*产品成本!$D$2+AH38*产品成本!$D$3+AI38*产品成本!$D$4 -> 1016.1268 | AK38: =AG38*产品成本!$E$2+AH38*产品成本!$E$3+AI38*产品成本!$E$4 -> 76.242275 | AL38: =AG38*产品成本!$F$2+AH38*产品成本!$F$3+AI38*产品成本!$F$4 -> 133.28 | AM38: =AG38*产品成本!$G$2+AH38*产品成本!$G$3+AI38*产品成本!$G$4 -> 1506.54 | AN38: =(E38-I38)*0.15 -> 1316.121 | AO38: =SUM(AJ38:AN38) -> 4048.31 | AP38: 4 | AQ38: 8 | AR38: 13 | AS38: =L38/(1-0.15+0.15*0.2) -> 490.13636 | AT38: =AP38*产品成本!$D$2+AQ38*产品成本!$D$3+AR38*产品成本!$D$4 -> 68.380282 | AU38: =AP38*产品成本!$E$2+AQ38*产品成本!$E$3+AR38*产品成本!$E$4 -> 4.9667493 | AV38: =AP38*产品成本!$F$2+AQ38*产品成本!$F$3+AR38*产品成本!$F$4 -> 8.5 | AX38: =AS38*0.15 -> 73.520455 | AY38: =-AX38*0.2 -> -14.704091 | AZ38: =SUM(AT38:AY38) -> 140.66339 | BA38: =AO38-AZ38 -> 3907.6466 | BB38: =E38-I38 -> 8774.14 | BC38: =E38-AS38-I38 -> 8284.0036 | BD38: =BC38-BA38-Z38 -> 1485.387 | BE38: =BD38/BC38 -> 0.17930786 | BG38: 7.4独立日，销量37，ACOAS=39.28%
A39: 0708~0711 | B39: PD2025 4 Days | C39: 542 | D39: 508 | E39: 10601.36 | F39: 0 | G39: 0 | H39: 0 | I39: 0 | J39: 30 | K39: =J39/C39 -> 0.055350554 | L39: 594.68 | M39: =(C39-C38)/C38 -> 0.38265306 | N39: =(D39-D38)/D38 -> 0.35466667 | O39: =(E39-E38)/E38 -> 0.20327385 | P39: =C39/D39 -> 1.0669291 | Q39: =E39/D39 -> 20.868819 | R39: =E39/C39 -> 19.559705 | S39: =C39/4 -> 135.5 | T39: =D39-Y39 -> 211 | U39: =T39/D39 -> 0.41535433 | V39: =Z39/(E39-I39) -> 0.25819517 | W39: 226717 | X39: 2425 | Y39: 297 | Z39: 2737.22 | AA39: 6015.47 | AB39: 1.13 | AC39: =Z39/AA39 -> 0.45503011 | AD39: =X39/W39 -> 0.010696154 | AE39: =Y39/X39 -> 0.12247423 | AF39: =Z39/Y39 -> 9.216229 | AG39: 143 | AH39: 187 | AI39: 212 | AJ39: =AG39*产品成本!$D$2+AH39*产品成本!$D$3+AI39*产品成本!$D$4 -> 1398.8732 | AK39: =AG39*产品成本!$E$2+AH39*产品成本!$E$3+AI39*产品成本!$E$4 -> 105.39756 | AL39: =AG39*产品成本!$F$2+AH39*产品成本!$F$3+AI39*产品成本!$F$4 -> 184.28 | AM39: =AG39*产品成本!$G$2+AH39*产品成本!$G$3+AI39*产品成本!$G$4 -> 2083.77 | AN39: =(E39-I39)*0.15 -> 1590.204 | AO39: =SUM(AJ39:AN39) -> 5362.5248 | AP39: 6 | AQ39: 13 | AR39: 4 | AS39: =L39/(1-0.15+0.15*0.2) -> 675.77273 | AT39: =AP39*产品成本!$D$2+AQ39*产品成本!$D$3+AR39*产品成本!$D$4 -> 53.380282 | AU39: =AP39*产品成本!$E$2+AQ39*产品成本!$E$3+AR39*产品成本!$E$4 -> 4.3879141 | AV39: =AP39*产品成本!$F$2+AQ39*产品成本!$F$3+AR39*产品成本!$F$4 -> 7.82 | AX39: =AS39*0.15 -> 101.36591 | AY39: =-AX39*0.2 -> -20.273182 | AZ39: =SUM(AT39:AY39) -> 146.68092 | BA39: =AO39-AZ39 -> 5215.8439 | BB39: =E39-I39 -> 10601.36 | BC39: =E39-AS39-I39 -> 9925.5873 | BD39: =BC39-BA39-Z39 -> 1972.5234 | BE39: =BD39/BC39 -> 0.19873115
A40: 0707~0713 | B40: 2025W28 | C40: 735 | D40: 694 | E40: 14720.75 | F40: 0 | G40: 0 | H40: 0 | I40: 0 | J40: 43 | K40: =J40/C40 -> 0.058503401 | L40: 855.49 | M40: =(C40-C39)/C39 -> 0.35608856 | N40: =(D40-D39)/D39 -> 0.36614173 | O40: =(E40-E39)/E39 -> 0.38857184 | P40: =C40/D40 -> 1.0590778 | Q40: =E40/D40 -> 21.211455 | R40: =E40/C40 -> 20.028231 | S40: =C40/7 -> 105 | T40: =D40-Y40 -> 229 | U40: =T40/D40 -> 0.32997118 | V40: =Z40/(E40-I40) -> 0.2748936 | W40: 331218 | X40: 3643 | Y40: 465 | Z40: 4046.64 | AA40: 9606.34 | AB40: 1.11 | AC40: =Z40/AA40 -> 0.4212468 | AD40: =X40/W40 -> 0.010998798 | AE40: =Y40/X40 -> 0.12764205 | AF40: =Z40/Y40 -> 8.7024516 | AG40: 197 | AH40: 261 | AI40: 277 | AJ40: =AG40*产品成本!$D$2+AH40*产品成本!$D$3+AI40*产品成本!$D$4 -> 1884.4366 | AK40: =AG40*产品成本!$E$2+AH40*产品成本!$E$3+AI40*产品成本!$E$4 -> 142.68881 | AL40: =AG40*产品成本!$F$2+AH40*产品成本!$F$3+AI40*产品成本!$F$4 -> 249.9 | AM40: =AG40*产品成本!$G$2+AH40*产品成本!$G$3+AI40*产品成本!$G$4 -> 2825.13 | AN40: =(E40-I40)*0.15 -> 2208.1125 | AO40: =SUM(AJ40:AN40) -> 7310.2679 | AP40: 10 | AQ40: 17 | AR40: 16 | AS40: =L40/(1-0.15+0.15*0.2) -> 972.14773 | AT40: =AP40*产品成本!$D$2+AQ40*产品成本!$D$3+AR40*产品成本!$D$4 -> 110 | AU40: =AP40*产品成本!$E$2+AQ40*产品成本!$E$3+AR40*产品成本!$E$4 -> 8.3735028 | AV40: =AP40*产品成本!$F$2+AQ40*产品成本!$F$3+AR40*产品成本!$F$4 -> 14.62 | AX40: =AS40*0.15 -> 145.82216 | AY40: =-AX40*0.2 -> -29.164432 | AZ40: =SUM(AT40:AY40) -> 249.65123 | BA40: =AO40-AZ40 -> 7060.6167 | BB40: =E40-I40 -> 14720.75 | BC40: =E40-AS40-I40 -> 13748.602 | BD40: =BC40-BA40-Z40 -> 2641.3456 | BE40: =BD40/BC40 -> 0.19211739
...

Sheet Toy
A1: 产品 | C1: 销售情况$ | W1: 广告$ | AG1: 销售成本$ | AQ1: 退款成本$ 退款部分的销售金额=系统退款金额/(1-0.15+0.2*0.15) | BC1: 汇总$
C2: 输入 | M2: 公式输出 | W2: 输入 | AC2: 公式输出 | AG2: 输入 | AK2: 公式输出 | AQ2: 输入 | AU2: 公式输出
A3: 日期 | B3: 周数 | C3: 销量 | D3: 订单量 | E3: 销售额 | F3: 促销销量 | G3: 促销订单量 | H3: 促销销售额 | I3: 促销折扣 | J3: 退款量 | K3: 退款率 | L3: 退款金额 | M3: 销量环比 | N3: 订单环比 | O3: 销售额环比 | P3: 客单 销量 | Q3: 客单 价格($) | R3: 销售 均价($) | S3: 日均 销量 | T3: 自然 订单 | U3: 自然单 占比(%) | V3: TAcos (%) | W3: 展示 | X3: 点击 | Y3: 广告订单量 | Z3: 广告花费 | AA3: 广告销售额 | AB3: CPC | AC3: Acos(%) | AD3: CTR(%) | AE3: CVR(%) | AF3: CPS(%) | AG3: Short w/oBall 1Pack | AH3: Long w/oBall 1Pack | AI3: w/Ball 1Pack | AJ3: Long w/oBall 2Pack | AK3: 产品成本 | AL3: 头程 | AM3: 入仓费 | AN3: FBA物流 | AO3: 佣金 | AP3: 成本小结 | AQ3: 退款Short w/oBall 1Pack | AR3: 退款Long w/oBall 1Pack | AS3: 退款w/Ball 1Pack | AT3: 退款Long w/oBall 2Pack | AU3: 退款 销售金额 | AV3: 退款 产品成本 | AW3: 退款头程 | AX3: 退款 入仓费 | AY3: 退款 FBA物流 | AZ3: 退款佣金 | BA3: 退款 管理费用 佣金的20% | BB3: 退款 成本小结 | BC3: 净成本 | BD3: 净销售额 | BE3: 净销售额 (-退款金额) | BF3: 毛利 | BG3: 毛利率 | BH3: BSR | BI3: 备注 | BJ3: 促销 | BK3: 列1
